Workbook

Sheet 2025年12月收支财务报表
C1: 2025年12月收支财务报表
C4: 财务统计 STATISTICS | G4: 12月收支明细 DETAIL | S4: =SUMIF(M:M,"广告配套",N:N) -> 5179.6729 | T4: U支出的广告配套（不含RMB支出）
G5: 序号 | H5: 日期 | I5: 收入 | M5: 支出
C6: 月份查询 | I6: 项目 | J6: 金额 | K6: 备注 | L6: 时间 | M6: 项目 | N6: 金额 | O6: 备注 | P6: 时间 | S6: =SUMIF(M:M,"后勤支出",N:N) -> 25910.27 | T6: 后勤支出
C7: 12月 | D7: ▼ | G7: 1 | H7: 45992 | I7: 11月结余 | J7: ='2025年11月收支财务报表'!C25 -> 26016.496 | S7: =SUMIF(M:M,"fb三不限10➕1Nancy",N:N) -> 2780.13 | T7: fb三不限10➕1Nancy | V7: =SUMIF(M:M,"wade shen 美金谷歌户25+5%",N:N) -> 0 | W7: wade shen 美金谷歌户
C8: 收入 | G8: 2 | H8: 45992 | M8: 广告配套 | N8: 50 | O8: BM*10 | P8: 0.44097222 | S8: =SUMIF(M:M,"B哥&谷歌充值9➕1Nancy",N:N) -> 320 | T8: B哥&谷歌充值9➕1Nancy
C9: =C21 -> 220076.63 | G9: 3 | H9: 45992 | M9: 广告配套 | N9: 14.24 | O9: 谷歌邮箱*8 | P9: 0.47013889 | S9: =SUMIF(M:M,"SZ_TK下户Chris Ryan",N:N) -> 474.28 | T9: SZ_TK下户Chris Ryan
C10: 支出 | G10: 4 | H10: 45992 | I10: 海总-新加坡、加拿大 | J10: 4000 | L10: 0.67569444 | M10: 广告配套 | N10: 288.86 | O10: IP: 40个 | P10: 0.45694444 | S10: =SUMIF(M:M,"印度企业户 欧洲美金户下户",N:N) -> 1140 | T10: 印度企业户 欧洲美金户下户 | V10: =SUMIF(M:M,"GT&SHEN 欧洲户新",N:N) -> 0 | W10: GT&SHEN 欧洲户新
C11: =C23 -> 198049.19 | G11: 5 | H11: 45992 | M11: 印度企业户 欧洲美金户下户 | N11: 1140 | O11: 1000*1.14=1140 | P11: 0.46111111 | S11: =SUMIF(M:M,"Y-5208 FB欧/美户",N:N) -> 4382.82 | T11: Y-5208 FB欧/美户 | V11: =SUMIF(M:M,"GT&papa 二不限",N:N) -> 0 | W11: GT&papa 二不限新
C12: 结余 | G12: 6 | H12: 45992 | M12: fb三不限10➕1Nancy | N12: 669.75 | O12: 1000*1.111-441.25=669.75 | P12: 5.0604167 | S12: =SUMIF(M:M,"谷歌共享户/老户",N:N) -> 1200 | T12: 谷歌共享户/老户
C13: =C9-C11 -> 22027.436 | G13: 7 | H13: 45993 | M13: SZ_TK下户Chris Ryan | N13: 474.28 | O13: (700-290.3)*1.06开户费+20*2=474.28 | P13: 0.94375 | S13: =SUMIF(M:M,"路人互动",N:N) -> 221.12 | T13: 路人互动 | V13: =SUMIF(M:M,"GT&SHEN 谷歌原生账单户",N:N) -> 0 | W13: GT&SHEN 谷歌原生账单户
G14: 8 | H14: 45994 | M14: 广告配套 | N14: 54.3 | O14: ADS续费 | P14: 0.48055556 | S14: =SUMIF(M:M,"志诚三不限",N:N) -> 3679.96 | T14: 志诚三不限
C15: 任意时段查询 | G15: 9 | H15: 45994 | M15: 后勤支出 | N15: 580.6 | O15: 580.6，ZZY的周结算11/22-11/30 | P15: 0.59375 | S15: =SUMIF(M:M,"路人互动系统",N:N) -> 643.86 | T15: 路人互动系统 | V15: =SUMIF(M:M,"启航",N:N) -> 0 | W15: 启航
C16: 起始日期： | G16: 10 | H16: 45994 | M16: 广告配套 | N16: 225 | O16: 防护续费 | P16: 0.59513889 | S16: =SUMIF(M:M,"GT&papa欧",N:N) -> 552.84 | T16: GT&papa欧 | V16: =SUMIF(M:M,"印度户印尼企业户",N:N) -> 0 | W16: 印度户印尼企业户
C17: 45292 | G17: 11 | H17: 45994 | M17: Y-5208 FB欧/美户 | N17: 320.04 | O17: ZZ 2900.38+309.0418-3,444.38=-234.9582；SZ 500*1.11=555 | P17: 0.61666667 | S17: =SUMIF(M:M,"星链-AdNova",N:N) -> 5629.83 | T17: 星链-AdNova | V17: =SUMIF(M:M,"海总新渠道",N:N) -> 0 | W17: 海总新渠道
C18: 结束日期： | G18: 12 | H18: 45994 | M18: 谷歌共享户/老户 | N18: 100 | O18: 开户费50*2=100 | P18: 0.68263889 | S18: =SUMIF(M:M,"大鱼速汇",N:N) -> 1010 | T18: 大鱼速汇 | V18: =SUMIF(M:M,"GT&海总 欧洲金融户",N:N) -> 0 | W18: GT&海总 欧洲金融户
C19: 72805 | G19: 13 | H19: 45994 | M19: Y-5208 FB欧/美户 | N19: 2775 | O19: 500*5*1.11=2775 | P19: 0.75694444 | S19: =SUMIF(M:M,"VCC-新系统",N:N) -> 4444 | T19: VCC-新系统 | V19: =SUMIF(M:M,"海总-黑泽",N:N) -> 0 | W19: 海总-黑泽
C20: 收入 | G20: 14 | H20: 45994 | M20: 路人互动系统 | N20: 107.68 | O20: 开户费50*2+随机金额0.68+6.55*1.07=107.68 | P20: 0.92013889 | S20: =SUMIF(M:M,"谷歌-饭团",N:N) -> 2260.2375 | T20: 谷歌-饭团
C21: =SUMIFS(J:J,H:H,">="&$C$17,H:H,"<="&$C$19) -> 220076.63 | G21: 15 | H21: 45995 | M21: 广告配套 | N21: 50 | O21: 工单 | P21: 0.68611111 | S21: =SUMIF(M:M,"风口猪充值广告费",N:N) -> 4687.84 | T21: 风口猪11月充值广告费
C22: 支出 | G22: 16 | H22: 45995 | M22: 志诚三不限 | N22: 1279.57 | O22: 182.1+1248.7+19*50+1690+1061.9-3853.13=1,279.57 | P22: 0.79166667 | S22: =SUMIF(M:M,"Anthony - FKZ - 6,5%",N:N) -> 213 | T22: Anthony - FKZ - 6,5% | V22: =SUMIF(M:M,"TK下户hailey",N:N) -> 0 | W22: TK下户hailey
C23: =SUMIFS(N:N,H:H,">="&$C$17,H:H,"<="&$C$19) -> 198049.19 | G23: 17 | H23: 45995 | M23: 谷歌共享户/老户 | N23: 1100 | O23: 500*2*1.10=1100 | P23: 21：02 | S23: =SUMIF(M:M,"Lolo - FKZ (~5% | dating)",N:N) -> 105 | T23: Lolo - FKZ (~5% | dating)
C24: 结余 | G24: 18 | H24: 45995 | M24: 路人互动 | N24: 221.12 | O24: （500-433.53）*1.07+开户费50*3=221.12 | P24: 0.87986111 | S24: =SUMIF(M:M,"十月二不限——（泰华）",N:N) -> 396 | T24: 十月二不限——（泰华） | V24: =SUMIF(M:M,"SZ-2_TK广告户-村长",N:N) -> 0 | W24: SZ-2_TK广告户-村长
C25: =C21-C23 -> 22027.436 | G25: 19 | H25: 45996 | I25: F2新加坡 | J25: 2400 | L25: 0.95694444 | M25: 广告配套 | N25: 255.1329 | O25: VPN续费 | P25: 0.43194444 | S25: =SUMIF(M:M,"二不限企业户",N:N) -> 483 | T25: 二不限企业户Makie
G26: 20 | H26: 45996 | M26: fb三不限10➕1Nancy | N26: 599.95 | O26: （500-4.99）*1.1*1.01+开户费50=599.95 | P26: 0.46875 | S26: =SUMIF(M:M,"凤凰渠道-泰华",N:N) -> 8226.19 | T26: 凤凰渠道-泰华
G27: 21 | H27: 45996 | M27: fb三不限10➕1Nancy | N27: 630.25 | O27: 500*1.05*1.01+开户费50*2=630.25 | P27: 0.57708333 | S27: =SUMIF(M:M,"风口猪12月充值广告费",N:N) -> 2167.81 | T27: 风口猪12月充值广告费
G28: 22 | H28: 45996 | M28: 广告配套 | N28: 14 | O28: 认证主页+普通主页 | P28: 0.75972222 | S28: =SUMIF(M:M,"流苏",N:N) -> 54600 | T28: 流苏
G29: 23 | H29: 45996 | M29: 广告配套 | N29: 2277.23 | O29: 明细：个号：60；中文认证主页：12；认证主页：109；主页：2；复审主页：6；复审BM：10 | P29: 0.76319444 | S29: =SUMIF(M:M,"岳总",N:N) -> 23250 | T29: 岳总
G30: 24 | H30: 45997 | M30: GT&papa欧 | N30: 140 | O30: 开户费20*7=140 | P30: 0.60277778 | S30: =SUMIF(M:M,"渠道106-本土fb🇯🇵",N:N) -> 29160 | T30: 渠道106-本土fb🇯🇵
G31: 25 | H31: 45997 | M31: Y-5208 FB欧/美户 | N31: 737.78 | O31: 其中SZ 500*1.11=555；DUNG备用金：500；Mad-shahe备用金：500；RED待付：（425.42-500）*1.11=82.78；ne待付：500*1.11=555；SP待付 ：1100；总待付：82.78+555+1100-500-500=737.78 | P31: 0.63055556 | S31: =SUMIF(M:M,"华侨粉测试 ",N:N) -> 2200 | T31: 华侨粉测试
G32: 26 | H32: 45997 | M32: 星链-AdNova | N32: 2166.93 | O32: SZ 开户费5*60+(1200-少算100-804.69)*1.08+上面的1,548.01=2,166.94 | P32: 0.69652778 | S32: =SUMIF(M:M,"印度资金测试",N:N) -> 12405 | T32: 印度资金测试
G33: 27 | H33: 45998 | I33: 海总-新加坡、加拿大 | J33: 4000 | L33: 0.82430556 | S33: =SUMIF(M:M,"官方授权户-15",N:N) -> 326.33 | T33: 官方授权户-15
G34: 28 | H34: 45999 | M34: 大鱼速汇 | N34: 101 | O34: 100*1.01=101 | P34: 0.44236111
G35: 29 | H35: 45999 | I35: 印度资金测试 | J35: 20000 | L35: 0.64722222 | M35: 谷歌-饭团 | N35: 373.2375 | O35: (500-163.75)*1.11=373.2375 | P35: 0.66319444
G36: 30 | H36: 45999 | M36: 大鱼速汇 | N36: 101 | O36: 100*1.01=101 | P36: 0.68194444
G37: 31 | H37: 45999 | M37: Y-5208 FB欧/美户 | N37: 550 | O37: 500*1.1=550 | P37: 0.70625
G38: 32 | H38: 45999 | M38: B哥&谷歌充值9➕1Nancy | N38: 320 | O38: 200*1.1+开户费100=320 | P38: 0.72569444
G39: 33 | H39: 45999 | I39: 华侨老头粉 | J39: 2200 | L39: 0.87916667 | M39: 华侨粉测试 | N39: 1100 | P39: 0.88958333
G40: 34 | H40: 46000 | M40: 路人互动系统 | N40: 107.17 | O40: 100*1.07+随机金额0.17=107.17 | P40: 0.44513889 | S40: =SUM(S4:S39) -> 198049.19 | T40: =C23-S40 -> 0
G41: 35 | H41: 46000 | M41: 大鱼速汇 | N41: 202 | O41: 200*1.01=202 | P41: 0.67222222
G42: 36 | H42: 46000 | M42: GT&papa欧 | N42: 283.84 | O42: SZ (50-29.6)*1.09=22.24；ZZ 240*1.09=261.6 | P42: 0.68888889 | S42: 往上支出-------------------分割线-------------------往下收入
...

Sheet 2025年11月收支财务报表
C1: 2025年11月收支财务报表
C4: 财务统计 STATISTICS | G4: 11月收支明细 DETAIL | S4: =SUMIF(M:M,"广告配套",N:N) -> 8873.59 | T4: U支出的广告配套（不含RMB支出）
G5: 序号 | H5: 日期 | I5: 收入 | M5: 支出
C6: 月份查询 | I6: 项目 | J6: 金额 | K6: 备注 | L6: 时间 | M6: 项目 | N6: 金额 | O6: 备注 | P6: 时间 | S6: =SUMIF(M:M,"后勤支出",N:N) -> 190060.25 | T6: 后勤支出
C7: 11月 | D7: ▼ | G7: 1 | H7: 45962 | I7: 10月结余 | J7: ='2025年10月收支财务报表'!C25 -> 221029.65 | M7: fb三不限10➕1Nancy | N7: 1150 | O7: 1000*1.11=1110+40=1150 | P7: 0.46805556 | S7: =SUMIF(M:M,"凤凰渠道-泰华",N:N) -> 2220 | T7: 凤凰渠道-泰华
C8: 收入 | G8: 2 | H8: 45962 | M8: GT&SHEN 欧洲户新 | N8: 218 | O8: ZZ 100*1.09=109：SZ 100*1.09=109 | P8: 0.62916667 | S8: =SUMIF(M:M,"wade shen 美金谷歌户25+5%",N:N) -> 633.93 | T8: wade shen 美金谷歌户 | U8: 已退
C9: =C21 -> 357273.99 | G9: 3 | H9: 45962 | I9: 渠道106-本土fb🇯🇵 | J9: 18000 | L9: 0.65694444 | M9: 岳总 | N9: 7500 | P9: 0.65972222 | S9: =SUMIF(M:M,"二不限企业户",N:N) -> 1414.78 | T9: 二不限企业户Makie | U9: 11/14 管控
C10: 支出 | G10: 4 | H10: 45962 | M10: GT&papa 二不限 | N10: 104 | O10: ZZ 100*1.04=104 | P10: 0.70069444 | S10: =SUMIF(M:M,"星链-AdNova",N:N) -> 25845.872 | T10: 星链-AdNova
C11: =C23 -> 331257.5 | G11: 5 | H11: 45962 | M11: GT&papa 二不限 | N11: 208 | O11: SZ 200*1.04=208 | P11: 0.86875 | S11: =SUMIF(M:M,"GT&SHEN 欧洲户新",N:N) -> 218 | T11: GT&SHEN 欧洲户新 | U11: 余额转谷歌了
C12: 结余 | G12: 6 | H12: 45962 | M12: 岳总 | N12: 9150 | P12: 0.94722222 | S12: =SUMIF(M:M,"fb三不限10➕1Nancy",N:N) -> 5394.88 | T12: fb三不限10➕1Nancy
C13: =C9-C11 -> 26016.496 | G13: 7 | H13: 45963 | I13: 渠道106-本土fb🇯🇵 | J13: 36000 | L13: 0.55763889 | M13: 广告配套 | N13: 14.15 | O13: 谷歌邮箱*5 | P13: 0.58888889 | S13: =SUMIF(M:M,"GT&papa 二不限",N:N) -> 312 | T13: GT&papa 二不限新 | U13: 11/17 封控
G14: 8 | H14: 45963 | M14: 二不限企业户 | N14: 1414.78 | O14: -1380.27*1.025=-1414.78 | P14: 0.59652778 | S14: =SUMIF(M:M,"岳总",N:N) -> 31650 | T14: 岳总
C15: 任意时段查询 | G15: 9 | H15: 45963 | M15: 岳总 | N15: 15000 | P15: 0.6625 | S15: =SUMIF(M:M,"GT&SHEN 谷歌原生账单户",N:N) -> 50 | T15: GT&SHEN 谷歌原生账单户 | U15: 余额转谷歌了
C16: 起始日期： | G16: 10 | H16: 45963 | M16: 广告配套 | N16: 240 | O16: 20端口 | P16: 0.67291667 | S16: =SUMIF(M:M,"路人互动",N:N) -> 5809.98 | T16: 路人互动
C17: 45292 | G17: 11 | H17: 45964 | I17: 华飞-Alex（三不限）8+千分6 | J17: 200 | K17: 退款 | L17: 0.44583333 | M17: 广告配套 | N17: 66 | O17: BM：10 | P17: 0.47222222 | S17: =SUMIF(M:M,"启航",N:N) -> 4633.29 | T17: 启航
C18: 结束日期： | G18: 12 | H18: 45964 | M18: wade shen 美金谷歌户25+5% | N18: 633.93 | O18: SZ 1000-368.44*1.075-30=633.93 | P18: 0.48958333 | S18: =SUMIF(M:M,"印度户印尼企业户",N:N) -> 5779.89 | T18: 印度户印尼企业户
C19: 72805 | G19: 13 | H19: 45964 | M19: 广告配套 | N19: 14.15 | O19: 谷歌邮箱*5 | P19: 0.50902778 | S19: =SUMIF(M:M,"海总新渠道",N:N) -> 1665 | T19: 海总新渠道
C20: 收入 | G20: 14 | H20: 45964 | M20: GT&SHEN 谷歌原生账单户 | N20: 50 | O20: 开户费50 | P20: 0.54722222 | S20: =SUMIF(M:M,"GT&海总 欧洲金融户",N:N) -> 387.63 | T20: GT&海总 欧洲金融户
C21: =SUMIFS(J:J,H:H,">="&$C$17,H:H,"<="&$C$19) -> 357273.99 | G21: 15 | H21: 45964 | M21: 后勤支出 | N21: 15000 | O21: 换汇 | P21: 0.64375 | S21: =SUMIF(M:M,"海总-黑泽",N:N) -> 3720.1875 | T21: 海总-黑泽
C22: 支出 | G22: 16 | H22: 45964 | I22: bc 的广告费 | J22: 10000 | L22: 0.70416667 | M22: 广告配套 | N22: 288.86 | O22: IP: 40个 | P22: 0.82569444 | S22: =SUMIF(M:M,"Y-5208 FB欧/美户",N:N) -> 4335.69 | T22: Y-5208 FB欧/美户
C23: =SUMIFS(N:N,H:H,">="&$C$17,H:H,"<="&$C$19) -> 331257.5 | G23: 17 | H23: 45964 | M23: 凤凰渠道-泰华 | N23: 2220 | O23: ZZ 2000*1.11=2220 | P23: 0.99027778 | S23: =SUMIF(M:M,"志诚三不限",N:N) -> 4652.83 | T23: 志诚三不限
C24: 结余 | G24: 18 | H24: 45964 | I24: Alex & Doris_谷歌户 | J24: 941.2 | K24: 退款 | L24: 0.99097222 | M24: 广告配套 | N24: 14.14 | O24: 谷歌邮箱*5 | P24: 0.44861111 | S24: =SUMIF(M:M,"SZ_TK下户Chris Ryan",N:N) -> 6107.85 | T24: SZ_TK下户Chris Ryan
C25: =C21-C23 -> 26016.496 | G25: 19 | H25: 45965 | M25: fb三不限10➕1Nancy | N25: 1110 | O25: ZZ 1000*1.11=1110 | P25: 0.49652778 | S25: =SUMIF(M:M,"TK下户hailey",N:N) -> 255 | T25: TK下户hailey
G26: 20 | H26: 45965 | M26: 后勤支出 | N26: 12056.74 | O26: B哥半年房租 | P26: 0.45416667 | S26: =SUMIF(M:M,"大鱼速汇",N:N) -> 808 | T26: 大鱼速汇
G27: 21 | H27: 45966 | M27: 后勤支出 | N27: 2270.9003 | O27: 发工资 | P27: 0.62569444 | S27: =SUMIF(M:M,"SZ-2_TK广告户-村长",N:N) -> 160 | T27: SZ-2_TK广告户-村长
G28: 22 | H28: 45966 | M28: 后勤支出 | N28: 4867.4742 | O28: 发工资 | P28: 0.62777778 | S28: =SUMIF(M:M,"谷歌-饭团",N:N) -> 1247.752 | T28: 谷歌-饭团
G29: 23 | H29: 45966 | M29: 后勤支出 | N29: 3434.0034 | O29: 发工资 | P29: 0.62916667 | S29: =SUMIF(M:M,"bc 的广告费",N:N) -> 4231.1 | T29: bc 的广告费退款
G30: 24 | H30: 45966 | M30: 后勤支出 | N30: 5425.2755 | O30: 发工资 | P30: 0.63125 | S30: =SUMIF(M:M,"德国单粉—summer FB180",N:N) -> 16470 | T30: 德国单粉—summer FB180
G31: 25 | H31: 45966 | M31: 后勤支出 | N31: 2487.7651 | O31: 发工资 | P31: 0.63333333 | S31: =SUMIF(M:M,"渠道BF 德国F",N:N) -> 4320 | T31: 渠道BF 德国F
G32: 26 | H32: 45966 | M32: 后勤支出 | N32: 1646.5457 | O32: 发工资 | P32: 0.63402778
G33: 27 | H33: 45966 | M33: 后勤支出 | N33: 5000 | O33: 发工资 | P33: 0.63611111 | S33: =SUM(S4:S31) -> 331257.5
G34: 28 | H34: 45966 | M34: 后勤支出 | N34: 10 | O34: 发工资 | P34: 0.6375
G35: 29 | H35: 45966 | M35: 后勤支出 | N35: 10 | O35: 发工资 | P35: 0.63819444 | S35: 往上支出-------------------分割线-------------------往下收入
G36: 30 | H36: 45966 | M36: 后勤支出 | N36: 10 | O36: 发工资 | P36: 0.63958333
G37: 31 | H37: 45966 | M37: 后勤支出 | N37: 10 | O37: 发工资 | P37: 0.64027778 | S37: =SUMIF(I:I,"渠道106-本土fb🇯🇵",J:J) -> 54000 | T37: 渠道106-本土fb🇯🇵 | U37: =S37+'2025年10月收支财务报表'!S46 -> 95760
G38: 32 | H38: 45966 | M38: 后勤支出 | N38: 10 | O38: 发工资 | P38: 0.64097222 | S38: =SUMIF(I:I,"bc 的广告费",J:J) -> 10000 | T38: bc 的广告费
G39: 33 | H39: 45966 | M39: 后勤支出 | N39: 10 | O39: 发工资 | P39: 0.64166667 | S39: =SUMIF(I:I,"新K4",J:J) -> 1173.97 | T39: 新K4
G40: 34 | H40: 45966 | M40: 后勤支出 | N40: 10 | O40: 发工资 | P40: 0.64305556 | S40: =SUMIF(I:I,"瑞典1梯队（蟑螂哥）结算群",J:J) -> 3420 | T40: 瑞典1梯队（蟑螂哥）结算群
G41: 35 | H41: 45966 | M41: 后勤支出 | N41: 10 | O41: 发工资 | P41: 0.64375 | S41: =SUMIF(I:I,"海总-新加坡、加拿大",J:J) -> 6300 | T41: 海总-新加坡、加拿大
G42: 36 | H42: 45966 | M42: 后勤支出 | N42: 10 | O42: 发工资 | P42: 0.64444444 | S42: =SUMIF(I:I,"德国单粉—summer FB180",J:J) -> 38000 | T42: 德国单粉—summer FB180
...

Sheet 2025年10月收支财务报表
C1: 2025年10月收支财务报表
C4: 财务统计 STATISTICS | G4: 10月收支明细 DETAIL | S4: =SUMIF(M:M,"广告配套",N:N) -> 9175.395 | T4: U支出的广告配套（不含RMB支出）
G5: 序号 | H5: 日期 | I5: 收入 | M5: 支出
C6: 月份查询 | I6: 项目 | J6: 金额 | K6: 备注 | L6: 时间 | M6: 项目 | N6: 金额 | O6: 备注 | P6: 时间 | S6: =SUMIF(M:M,"后勤支出",N:N) -> 31523.68 | T6: 后勤支出
C7: 10月 | D7: ▼ | G7: 1 | H7: 45931 | I7: 9月结余 | J7: ='2025年9月收支财务报表'!C25 -> 19233.42 | S7: =SUMIF(M:M,"印度户印尼企业户",N:N) -> 213183.14 | T7: 印度户印尼企业户
C8: 收入 | G8: 2 | H8: 45931 | I8: 白马4期 | J8: 30000 | L8: 0.64166667 | S8: =SUMIF(M:M,"Vcc-102524 服务费1（泰华）",N:N) -> 404 | T8: Vcc-102524 服务费1（泰华）
C9: =C21 -> 772527.52 | G9: 3 | H9: 45932 | M9: 印度户印尼企业户 | N9: 14780.99 | O9: 充值金额13649.06263+手续费1131.925011=14,780.99 | P9: 0.73055556 | S9: =SUMIF(M:M,"凤凰渠道-泰华",N:N) -> 182993.43 | T9: 凤凰渠道-泰华
C10: 支出 | G10: 4 | H10: 45932 | M10: 广告配套 | N10: 78.57 | O10: 个号*10 | P10: 0.83541667 | S10: =SUMIF(M:M,"wade shen 美金谷歌户25+5%",N:N) -> 195.5 | T10: wade shen 美金谷歌户25+5%
C11: =C23 -> 551497.86 | G11: 5 | H11: 45933 | M11: 广告配套 | N11: 25.45 | O11: 谷歌邮箱*5 | P11: 0.42430556 | S11: =SUMIF(M:M,"二不限企业户",N:N) -> 7612.44 | T11: 二不限企业户
C12: 结余 | G12: 6 | H12: 45933 | M12: 广告配套 | N12: 33 | O12: 个号*5 | P12: 0.72847222 | S12: =SUMIF(M:M,"Y-5208 FB欧/美户",N:N) -> 1374.31 | T12: Y-5208 FB欧/美户
C13: =C9-C11 -> 221029.65 | G13: 7 | H13: 45933 | M13: 三不限美国户-8%小鱼 | N13: 540 | O13: 500*1.08=540 | P13: 0.59166667 | S13: =SUMIF(M:M,"三不限美国户-8%小鱼",N:N) -> 540 | T13: 三不限美国户-8%小鱼
G14: 8 | H14: 45933 | M14: 后勤支出 | N14: 10000 | O14: 换汇 | P14: 0.74097222 | S14: =SUMIF(M:M,"十月二不限",N:N) -> 5255.56 | T14: 十月二不限
C15: 任意时段查询 | G15: 9 | H15: 45934 | I15: 白马4期 | J15: 30000 | L15: 14：18 | M15: 印度户印尼企业户 | N15: 6455.82 | O15: 充值金额5940.570042+手续费515.2456034=6,455.82 | P15: 12：08 | S15: =SUMIF(M:M,"Alex_1011——谷歌原生户",N:N) -> 4783 | T15: Alex_1011——谷歌原生户
C16: 起始日期： | G16: 10 | H16: 45935 | M16: 广告配套 | N16: 288.86 | O16: IP*40个 | P16: 20：22 | S16: =SUMIF(M:M,"启航",N:N) -> 2189.82 | T16: 启航
C17: 45292 | G17: 11 | H17: 45936 | M17: 广告配套 | N17: 210.55 | O17: 耐用号*5 | P17: 11：13 | S17: =SUMIF(M:M,"HC ADS Agency 2 2026",N:N) -> 53.5 | T17: HC ADS Agency 2 2026
C18: 结束日期： | G18: 12 | H18: 45936 | M18: 印度户印尼企业户 | N18: 18063.14 | O18: 充值金额16678.84+手续费1384.31=18,063.14 | P18: 0.47291667 | S18: =SUMIF(M:M,"泰华 & Bigad 谷歌老户 8+1",N:N) -> 3461.4 | T18: 泰华 & Bigad 谷歌老户 8+1
C19: 72805 | G19: 13 | H19: 45936 | M19: 十月二不限 | N19: 516.36 | O19: ZZ (100*3-295)*1.02+开户费30=35.1，SZ (100*5*-87)1.02+开户费30*2=481.26，合计516.36 | P19: 0.64652778 | S19: =SUMIF(M:M,"wade 谷歌户（阿水）",N:N) -> 686 | T19: wade 谷歌户（阿水）
C20: 收入 | G20: 14 | H20: 45936 | M20: 广告配套 | N20: 225 | O20: 防护续费 | P20: 15：41 | S20: =SUMIF(M:M,"海总-黑泽",N:N) -> 3967.8 | T20: 海总-黑泽
C21: =SUMIFS(J:J,H:H,">="&$C$17,H:H,"<="&$C$19) -> 772527.52 | G21: 15 | H21: 45936 | I21: K26/印度股票 | J21: 30000 | L21: 0.65555556 | M21: Vcc-102524 服务费1（泰华） | N21: 404 | O21: 400*1.01=404 | P21: 0.6625 | S21: =SUMIF(M:M,"谷歌-otto",N:N) -> 333.3 | T21: 谷歌-otto
C22: 支出 | G22: 16 | H22: 45937 | M22: 印度户印尼企业户 | N22: 13884.26 | O22: 充值金额12800.24+手续费1084.02=13,884.26 | P22: 12：51 | S22: =SUMIF(M:M,"星链-AdNova",N:N) -> 1140 | T22: 星链-AdNova
C23: =SUMIFS(N:N,H:H,">="&$C$17,H:H,"<="&$C$19) -> 551497.86 | G23: 17 | H23: 45937 | I23: K26/印度股票 | J23: 20000 | L23: 22：37 | S23: =SUMIF(M:M,"志诚三不限",N:N) -> 278.89 | T23: 志诚三不限
C24: 结余 | G24: 18 | H24: 45938 | I24: 路人互动 | J24: 2480.7 | L24: 13：44 | M24: 印度户印尼企业户 | N24: 8403.65 | O24: 充值金额7781.16+手续费622.49=8,403.65 | P24: 0.67777778 | S24: =SUMIF(M:M,"SHEN@FLZ 2 群",N:N) -> 14241.7 | T24: SHEN@FLZ 2 群
C25: =C21-C23 -> 221029.65 | G25: 19 | H25: 45938 | M25: 二不限企业户 | N25: 420.36 | O25: (800-381.08)*1.025=429.39，实转420.36，少转9.03 | P25: 22：28 | S25: =SUMIF(M:M,"GT&SHEN 欧洲户新",N:N) -> 218 | T25: GT&SHEN 欧洲户新
G26: 20 | H26: 45939 | M26: wade shen 美金谷歌户25+5% | N26: 140.03 | O26: (清零1133.54-充值1087.06)*1.075-开户费190= -140.03 | P26: 11：43 | S26: =SUMIF(M:M,"GT二不限新",N:N) -> 60 | T26: GT二不限新
G27: 21 | H27: 45939 | M27: 广告配套 | N27: 16.11 | O27: 谷歌邮箱4个 | P27: 11：49 | S27: =SUMIF(M:M,"印度20期",N:N) -> 1371 | T27: 印度20期
G28: 22 | H28: 45939 | M28: 广告配套 | N28: 20 | O28: GPT订阅19.8*1.01=20 | P28: 11：58 | S28: =SUMIF(M:M,"岳总",N:N) -> 32100 | T28: 岳总
G29: 23 | H29: 45939 | M29: 广告配套 | N29: 50.5 | O29: GPT订阅50*1.01=50.5 | P29: 12：11 | S29: =SUMIF(M:M,"海总-比利时单导测试",N:N) -> 2800 | T29: 海总-比利时单导测试
G30: 24 | H30: 45939 | M30: 后勤支出 | N30: 805.33 | O30: 发工资 | P30: 15：19 | S30: =SUMIF(M:M,"赵总",N:N) -> 25050 | T30: 赵总
G31: 25 | H31: 45939 | M31: 后勤支出 | N31: 1800 | O31: 发工资 | P31: 15：23 | S31: =SUMIF(M:M,"新K1/B哥",N:N) -> 6506 | T31: 新K1/B哥
G32: 26 | H32: 45939 | M32: 后勤支出 | N32: 1157.56 | O32: 发工资 | P32: 0.64305556
G33: 27 | H33: 45939 | M33: 后勤支出 | N33: 1269.56 | O33: 发工资 | P33: 0.64444444 | S33: =SUM(S4:S31) -> 551497.86
G34: 28 | H34: 45939 | M34: 后勤支出 | N34: 1326.41 | O34: 发工资 | P34: 0.64722222
G35: 29 | H35: 45939 | M35: 后勤支出 | N35: 2607.56 | O35: 发工资 | P35: 0.64861111 | S35: 往上支出-------------------分割线-------------------往下收入
G36: 30 | H36: 45939 | M36: 后勤支出 | N36: 845.07 | O36: 发工资 | P36: 15：37
G37: 31 | H37: 45939 | M37: 后勤支出 | N37: 1185.56 | O37: 发工资 | P37: 15：40 | S37: =SUMIF(I:I,"白马4期",J:J) -> 60000 | T37: 白马4期 | U37: =S37+'2025年9月收支财务报表'!S40 -> 120000
G38: 32 | H38: 45939 | M38: 后勤支出 | N38: 5000 | O38: 发工资 | P38: 15：42 | S38: =SUMIF(I:I,"K26/印度股票",J:J) -> 144212 | T38: K26/印度股票
G39: 33 | H39: 45939 | M39: 后勤支出 | N39: 280 | O39: 发工资 | P39: 15：44 | S39: =SUMIF(I:I,"B哥/马来英语粉",J:J) -> 40000 | T39: B哥/马来英语粉 | U39: =S39+'2025年9月收支财务报表'!S46 -> 60000
G40: 34 | H40: 45939 | M40: Y-5208 FB欧/美户 | N40: 1374.31 | O40: 1110+1120-855.69=1374.31 | P40: 16：23 | S40: =SUMIF(I:I,"新K1/B哥",J:J) -> 170000 | T40: 新K1/B哥
G41: 35 | H41: 45939 | M41: 广告配套 | N41: 14 | O41: 飞机会员 | P41: 18：20 | S41: =SUMIF(I:I,"新K4/B哥",J:J) -> 135067 | T41: 新K4/B哥
G42: 36 | H42: 45939 | I42: K26/印度股票 | J42: 20000 | L42: 18：54 | M42: 二不限企业户 | N42: 615 | O42: 600*1.025=615 | P42: 0.95486111 | S42: =SUMIF(I:I,"海总-比利时单导测试",J:J) -> 2800 | T42: 海总-比利时单导测试
...

Sheet 2025年9月收支财务报表
C1: 2025年9月收支财务报表
C4: 财务统计 STATISTICS | G4: 9月收支明细 DETAIL | S4: =SUMIF(M:M,"广告配套",N:N) -> 10833.788 | T4: U支出的广告配套（不含RMB支出）
G5: 序号 | H5: 日期 | I5: 收入 | M5: 支出
C6: 月份查询 | I6: 项目 | J6: 金额 | K6: 备注 | L6: 时间 | M6: 项目 | N6: 金额 | O6: 备注 | P6: 时间 | S6: =SUMIF(M:M,"后勤支出",N:N) -> 47962.486 | T6: 后勤支出
C7: 9月 | D7: ▼ | G7: 1 | H7: 45901 | I7: 8月结余 | J7: ='2025年8月收支财务报表'!C25 -> 112330.75 | M7: 广告配套 | N7: 210.36 | O7: 耐用号*5 | P7: 0.61458333 | S7: =SUMIF(M:M,"GT&SHEN 欧洲户８＋１ 港60+5+1",N:N) -> 77971.79 | T7: GT&SHEN 欧洲户８＋１ 港60+5+1
C8: 收入 | G8: 2 | H8: 45901 | M8: 广告配套 | N8: 24.57 | O8: IP | P8: 17：01 | S8: =SUMIF(M:M,"志诚三不限",N:N) -> 35281.28 | T8: 志诚三不限
C9: =C21 -> 413986.89 | G9: 3 | H9: 45901 | M9: 广告配套 | N9: 26.25 | O9: IP2 | P9: 0.71388889 | S9: =SUMIF(M:M,"海总新渠道",N:N) -> 1110 | T9: 海总新渠道
C10: 支出 | G10: 4 | H10: 45901 | I10: 马来英_阿稳 | J10: 840 | K10: 退款 | L10: 0.82013889 | M10: GT&SHEN 欧洲户８＋１ 港60+5+1 | N10: 540 | O10: 500*1.08=540 | P10: 0.86319444 | S10: =SUMIF(M:M,"印度户印尼企业户",N:N) -> 90763.63 | T10: 印度户印尼企业户
C11: =C23 -> 394753.47 | G11: 5 | H11: 45901 | M11: 志诚三不限 | N11: 2058.46 | O11: 500*2*1.11=1110 | P11: 0.95763889 | S11: =SUMIF(M:M,"路人互动",N:N) -> 15002.96 | T11: 路人互动
C12: 结余 | G12: 6 | H12: 45902 | M12: 海总新渠道 | N12: 1110 | P12: 0.49722222 | S12: =SUMIF(M:M,"Vcc-102524 服务费1（泰华）",N:N) -> 404 | T12: Vcc-102524 服务费1（泰华）
C13: =C9-C11 -> 19233.42 | G13: 7 | H13: 45902 | M13: 广告配套 | N13: 59 | O13: 个号 10个 | P13: 0.54375 | S13: =SUMIF(M:M,"印度企业户 欧洲美金户",N:N) -> 1056.3 | T13: 印度企业户 欧洲美金户
G14: 8 | H14: 45902 | M14: 广告配套 | N14: 288.86 | O14: IP | P14: 0.67638889 | S14: =SUMIF(M:M,"凤凰渠道-泰华",N:N) -> 14511.09 | T14: 凤凰渠道-泰华
C15: 任意时段查询 | G15: 9 | H15: 45902 | M15: 后勤支出 | N15: 60 | O15: 营业执照 | P15: 0.68472222 | S15: =SUMIF(M:M,"海总-黑泽",N:N) -> 4423.2 | T15: 海总-黑泽
C16: 起始日期： | G16: 10 | H16: 45902 | M16: 广告配套 | N16: 500 | O16: 个号预存 | P16: 0.69791667 | S16: =SUMIF(M:M,"Alex & Doris_谷歌户",N:N) -> 1110 | T16: Alex & Doris_谷歌户
C17: 45292 | G17: 11 | H17: 45902 | M17: 广告配套 | N17: 34.285 | O17: 个号 3个 | P17: 0.72777778 | S17: =SUMIF(M:M,"wade shen 美金谷歌户25+5%",N:N) -> 1247.5 | T17: wade shen 美金谷歌户25+5%
C18: 结束日期： | G18: 12 | H18: 45902 | M18: 广告配套 | N18: 20 | O18: 老主页2个 | P18: 0.73333333 | S18: =SUMIF(M:M,"GT二不限",N:N) -> 1765.12 | T18: GT二不限
C19: 72805 | G19: 13 | H19: 45902 | M19: 渠道L 英文L 马来 | N19: 3960 | O19: 退款 | P19: 19：22 | S19: =SUMIF(M:M,"谷歌户（阿水）",N:N) -> 300 | T19: 谷歌户（阿水）
C20: 收入 | G20: 14 | H20: 45902 | M20: 志诚三不限 | N20: 3062.1 | O20: 2640+422.1=3062.1 | P20: 0.99930556 | S20: =SUMIF(M:M,"6% 海外户",N:N) -> 455.84 | T20: 6% 海外户
C21: =SUMIFS(J:J,H:H,">="&$C$17,H:H,"<="&$C$19) -> 413986.89 | G21: 15 | H21: 45903 | M21: 广告配套 | N21: 59 | O21: BM：10个 | P21: 0.53194444 | S21: =SUMIF(M:M,"深圳芳林子",N:N) -> 3454.2 | T21: 深圳芳林子
C22: 支出 | G22: 16 | H22: 45903 | M22: 印度户印尼企业户 | N22: 8499.15 | O22: 7841.81+657.34=8499.15 | P22: 0.53402778 | S22: =SUMIF(M:M,"二不限企业户",N:N) -> 820 | T22: 二不限企业户
C23: =SUMIFS(N:N,H:H,">="&$C$17,H:H,"<="&$C$19) -> 394753.47 | G23: 17 | H23: 45903 | M23: 广告配套 | N23: 10.0369 | O23: 飞机号预存 | P23: 0.55625 | S23: =SUMIF(M:M,"华飞-Alex（三不限）8+千分6",N:N) -> 334.596 | T23: 华飞-Alex（三不限）8+千分6
C24: 结余 | G24: 18 | H24: 45903 | M24: 后勤支出 | N24: 10000 | O24: 换汇RMB | P24: 0.56111111 | S24: =SUMIF(M:M,"Y-5208 FB欧/美户",N:N) -> 2260 | T24: Y-5208 FB欧/美户
C25: =C21-C23 -> 19233.42 | G25: 19 | H25: 45903 | M25: 后勤支出 | N25: 10000 | O25: 换汇RMB2 | P25: 14：30 | S25: =SUMIF(M:M,"三不限美国户-8%小鱼",N:N) -> 1080 | T25: 三不限美国户-8%小鱼
G26: 20 | H26: 45903 | M26: 广告配套 | N26: 9.98 | O26: fbspider单月套餐A | P26: 0.65 | S26: =SUMIF(M:M,"潘安户",N:N) -> 218.16 | T26: 潘安户
G27: 21 | H27: 45903 | I27: 十月二不限 | J27: 55.7 | K27: 退款 | L27: 0.92847222 | S27: =SUMIF(M:M,"企业户",N:N) -> 152.53 | T27: 企业户
G28: 22 | H28: 45904 | I28: 西班牙大区1组资源-张小强 | J28: 3960 | K28: 9月1-2日 西班牙大区1组资源-张小强 9/1 F50 有效 11 9/2 F50 有效25 合计: (11+25)*110=3960 | L28: 0.033333333 | M28: 广告配套 | N28: 118 | O28: BM：10个，个号：10个 | P28: 0.49305556 | S28: =SUMIF(M:M,"Jay",N:N) -> 9600 | T28: Jay
G29: 23 | H29: 45904 | I29: 欧洲户10➕1-Nancy | J29: 481.56 | K29: 退款 | L29: 0.57708333 | M29: 广告配套 | N29: $0.48 | O29: 谷歌邮箱1个 | P29: 0.63055556 | S29: =SUMIF(M:M,"岳总",N:N) -> 42920 | T29: 岳总
G30: 24 | H30: 45904 | M30: GT&SHEN 欧洲户８＋１ 港60+5+1 | N30: 218 | O30: 200*1.09=218 | P30: 0.67916667 | S30: =SUMIF(M:M,"晨",N:N) -> 5250 | T30: 晨
G31: 25 | H31: 45904 | I31: 客户服务群-L0816 | J31: 695.49 | K31: 退款 | L31: 18：01 | S31: =SUMIF(M:M,"意大利3期",N:N) -> 20505 | T31: 意大利3期
G32: 26 | H32: 45904 | I32: 西班牙大区1组资源-张小强 | J32: 2090 | K32: 9月3日 西班牙大区1组资源-张小强 9/3 T5 有效 19 合计: 19*110=2090 | L32: 18：11 | M32: 志诚三不限 | N32: 3352.29 | O32: (1020-9.45)*1.07+开户费60+500-500+2010*1.1=3,352.29 | P32: 23：08 | S32: =SUMIF(M:M,"渠道L 英文L 马来",N:N) -> 3960 | T32: 渠道L 英文L 马来
G33: 27 | H33: 45905 | I33: 西班牙大区1组资源-张小强 | J33: 2200 | K33: 9月5日 西班牙大区1组资源-张小强 9/5 C68有效20 合计: 20*110=2200 | L33: 0.51319444 | M33: 后勤支出 | N33: 3511.8189 | O33: 发工资 | P33: 0.63263889
G34: 28 | H34: 45905 | I34: 拉总（印度） | J34: 576 | L34: 0.63333333 | M34: 后勤支出 | N34: 1800 | O34: 发工资 | P34: 0.63611111 | S34: =SUM(S4:S32) -> 394753.47
G35: 29 | H35: 45905 | M35: 后勤支出 | N35: 1263.9556 | O35: 发工资 | P35: 0.63888889
G36: 30 | H36: 45905 | M36: 后勤支出 | N36: 2002.0444 | O36: 发工资 | P36: 0.64166667 | S36: 往上支出-------------------分割线-------------------往下收入
G37: 31 | H37: 45905 | M37: 后勤支出 | N37: 555.55556 | O37: 发工资 | P37: 0.64305556
G38: 32 | H38: 45905 | M38: 后勤支出 | N38: 695.55556 | O38: 发工资 | P38: 0.64513889 | S38: =SUMIF(I:I,"西班牙大区1组资源-张小强",J:J) -> 9680 | T38: 西班牙大区1组资源-张小强
G39: 33 | H39: 45905 | M39: 后勤支出 | N39: 555.55556 | O39: 发工资 | P39: 0.64583333 | S39: =SUMIF(I:I,"拉总（印度）",J:J) -> 576 | T39: 拉总（印度）
G40: 34 | H40: 45905 | M40: 后勤支出 | N40: 5000 | O40: 发工资 | P40: 0.64722222 | S40: =SUMIF(I:I,"白马4期",J:J) -> 60000 | T40: 白马4期
G41: 35 | H41: 45905 | M41: 意大利3期 | N41: 20505 | O41: 退款 | P41: 0.65625 | S41: =SUMIF(I:I,"渠道BF 新加坡L",J:J) -> 2700 | T41: 渠道BF 新加坡L
G42: 36 | H42: 45905 | M42: 广告配套 | N42: 89 | O42: 个号：15个 | P42: 15：57 | S42: =SUMIF(I:I,"印度18期",J:J) -> 123944 | T42: 印度18期
...

Sheet 2025年8月收支财务报表
C1: 2025年8月收支财务报表
C4: 财务统计 STATISTICS | G4: 8月收支明细 DETAIL | S4: =SUMIF(M:M,"广告配套",N:N) -> 7033.375 | T4: U支出的广告配套（不含RMB支出）
G5: 序号 | H5: 日期 | I5: 收入 | M5: 支出
C6: 月份查询 | I6: 项目 | J6: 金额 | K6: 备注 | L6: 时间 | M6: 项目 | N6: 金额 | O6: 备注 | P6: 时间 | S6: =SUMIF(M:M,"后勤支出",N:N) -> 417091.94 | T6: 后勤支出
C7: 8月 | D7: ▼ | G7: 1 | H7: 45870 | I7: 7月结余 | J7: ='2025年7月收支财务报表'!C25 -> 368534.27 | M7: 广告配套 | N7: 40 | O7: WS技术号3个 | P7: 0.56666667 | S7: =SUMIF(M:M,"深圳芳林子",N:N) -> 570.65 | T7: 深圳芳林子
C8: 收入 | G8: 2 | H8: 45870 | I8: 德国股票粉（1）组【张小强】 | J8: 7520 | K8: 7月31日 德国股票粉（1）组【张小强】 7/31 F17群 有效12 7/31 Q3 有效8 7/31 A3 有效27 合计: （12+8+27）*160=7520 | L8: 0.61458333 | M8: 凤凰渠道-泰华 | N8: 6601.28 | O8: (7115.57-1427.5)*1.15+30*2=6601.28 | P8: 0.67916667 | S8: =SUMIF(M:M,"印度企业户 欧洲美金户",N:N) -> 10544.56 | T8: 印度企业户 欧洲美金户
C9: =C21 -> 888102.54 | G9: 3 | H9: 45870 | M9: 凤凰渠道-泰华 | N9: 8424.59 | O9: (8441.3-1115.57)*1.15=8,424.59 | P9: 0.89930556 | S9: =SUMIF(M:M,"凤凰渠道-泰华",N:N) -> 48872.05 | T9: 凤凰渠道-泰华
C10: 支出 | G10: 4 | H10: 45871 | M10: 广告配套 | N10: 500 | O10: 矿工费 | P10: 0.43611111 | S10: =SUMIF(M:M,"Vcc-102524 服务费1（泰华）",N:N) -> 202 | T10: Vcc-102524 服务费1（泰华）
C11: =C23 -> 775771.79 | G11: 5 | H11: 45871 | I11: 德国股票粉（1）组【张小强】 | J11: 3040 | K11: 7月31日 德国股票粉（1）组【张小强】 7/31 J3 有效8 7/31 A1有效9 S5有效2 共计有效11 合计: （8+9+2）*160=3040 | L11: 0.69722222 | M11: 凤凰渠道-泰华 | N11: 12075 | O11: 0500*1.15=12075 | P11: 17：26 | S11: =SUMIF(M:M,"🌹R|泰华&云峰合作群美金企业户12+1",N:N) -> 2262.4 | T11: 🌹R|泰华&云峰合作群美金企业户12+1
C12: 结余 | G12: 6 | H12: 45871 | M12: 凤凰渠道-泰华 | N12: 4600 | O12: 4000*1.15=4600 | P12: 0.92638889 | S12: =SUMIF(M:M,"GT&SHEN 欧洲户８＋１ 港60+5+1",N:N) -> 13287.51 | T12: GT&SHEN 欧洲户８＋１ 港60+5+1
C13: =C9-C11 -> 112330.75 | G13: 7 | H13: 45871 | M13: 广告配套 | N13: 101.5 | O13: 账单户2 | P13: 0.97569444 | S13: =SUMIF(M:M,"印度户印尼企业户",N:N) -> 29569.46 | T13: 印度户印尼企业户
G14: 8 | H14: 45871 | M14: Vcc-102524 服务费1（泰华） | N14: 202 | O14: 200*1.01=202 | P14: 0.99375 | S14: =SUMIF(M:M,"Y-5208 FB欧/美户",N:N) -> 5075 | T14: Y-5208 FB欧/美户
C15: 任意时段查询 | G15: 9 | H15: 45872 | M15: 凤凰渠道-泰华 | N15: 4600 | O15: 4000*1.15=4600 | P15: 0.99861111 | S15: =SUMIF(M:M,"印尼企业户",N:N) -> 1150 | T15: 印尼企业户
C16: 起始日期： | G16: 10 | H16: 45872 | M16: 后勤支出 | N16: 37375.427 | O16: 7月分红-LH，373754.27*10%=37375.427 | P16: 0.57291667 | S16: =SUMIF(M:M,"客户服务群-L0816",N:N) -> 3129 | T16: 客户服务群-L0816
C17: 45292 | G17: 11 | H17: 45872 | M17: 后勤支出 | N17: 168189.42 | O17: 7月分红- B哥 373754.27*0.45=168189.4215 | P17: 0.59097222 | S17: =SUMIF(M:M,"志诚三不限",N:N) -> 11710.95 | T17: 志诚三不限
C18: 结束日期： | G18: 12 | H18: 45872 | M18: 广告配套 | N18: 18 | O18: 老主页：5 | P18: 0.64305556 | S18: =SUMIF(M:M,"黑泽",N:N) -> 60 | T18: 黑泽
C19: 72805 | G19: 13 | H19: 45872 | M19: 凤凰渠道-泰华 | N19: 7475 | O19: 6500*1.15=7475 | P19: 0.75486111 | S19: =SUMIF(M:M,"欧洲户10➕1-Nancy",N:N) -> 1665 | T19: 欧洲户10➕1-Nancy
C20: 收入 | G20: 14 | H20: 45873 | M20: 后勤支出 | N20: 10000 | O20: 换汇RMB | P20: 0.81388889 | S20: =SUMIF(M:M,"海总新渠道",N:N) -> 1080 | T20: 海总新渠道
C21: =SUMIFS(J:J,H:H,">="&$C$17,H:H,"<="&$C$19) -> 888102.54 | G21: 15 | H21: 45873 | M21: 广告配套 | N21: 1010 | O21: 主页：15 ；老主页：36；千粉主页：50；个号：45；三解：10；BM15 | P21: 0.62291667 | S21: =SUMIF(M:M,"路人互动",N:N) -> 779.89 | T21: 路人互动
C22: 支出 | G22: 16 | H22: 45873 | M22: 凤凰渠道-泰华 | N22: 5096.18 | O22: (7000-2568.54)*1.15=5096.18 | P22: 22：31 | S22: =SUMIF(M:M,"马来英_阿稳",N:N) -> 11440 | T22: 马来英_阿稳
C23: =SUMIFS(N:N,H:H,">="&$C$17,H:H,"<="&$C$19) -> 775771.79 | G23: 17 | H23: 45874 | M23: 🌹R|泰华&云峰合作群美金企业户12+1 | N23: 1131.2 | O23: 1000*1.12*1.01= 1,131.2 | P23: 0.9625 | S23: =SUMIF(M:M,"德国德语-阿稳",N:N) -> 2600 | T23: 德国德语-阿稳
C24: 结余 | G24: 18 | H24: 45874 | M24: 后勤支出 | N24: 15024.343 | O24: 发工资 | P24: 0.6375 | S24: =SUMIF(M:M,"海总-小日子，意大利🇮🇹",N:N) -> 5000 | T24: 海总-小日子，意大利🇮🇹
C25: =C21-C23 -> 112330.75 | G25: 19 | H25: 45874 | M25: 后勤支出 | N25: 10434.579 | O25: 发工资 | P25: 0.64166667 | S25: =SUMIF(M:M,"阿稳-IN",N:N) -> 17280 | T25: 阿稳-IN
G26: 20 | H26: 45874 | M26: 后勤支出 | N26: 13790.168 | O26: 发工资 | P26: 0.63888889 | S26: =SUMIF(M:M,"印度23期",N:N) -> 12060 | T26: 印度23期 | U26: 退款
G27: 21 | H27: 45874 | M27: 后勤支出 | N27: 697.64789 | O27: 发工资 | P27: 0.64236111 | S27: =SUMIF(M:M,"B1印度",N:N) -> 24064 | T27: B1印度 | U27: 退款
G28: 22 | H28: 45874 | M28: 后勤支出 | N28: 7775.2256 | O28: 发工资 | P28: 0.64027778 | S28: =SUMIF(M:M,"海总-德国；意大利",N:N) -> 105935 | T28: 海总-德国；意大利
G29: 23 | H29: 45874 | M29: 后勤支出 | N29: 7738.063 | O29: 发工资 | P29: 0.64375 | S29: =SUMIF(M:M,"印度驻场-lala(郑总）",N:N) -> 43309 | T29: 印度驻场-lala(郑总）
G30: 24 | H30: 45874 | M30: 后勤支出 | N30: 6175.9153 | O30: 发工资 | P30: 0.64513889 | S30: =SUM(S4:S29) -> 775771.79
G31: 25 | H31: 45874 | M31: 后勤支出 | N31: 6701.7337 | O31: 发工资 | P31: 0.64652778
G32: 26 | H32: 45874 | M32: 后勤支出 | N32: 5000 | O32: 发工资 | P32: 0.64722222 | S32: 往上支出-------------------分割线-------------------往下收入
G33: 27 | H33: 45874 | I33: 阿水 印度mom 11+1 | J33: 4222.37 | K33: 退款 | L33: 0.72222222
G34: 28 | H34: 45874 | I34: 印度15期 | J34: 16772 | K34: 14期补粉 | L34: 0.79444444 | S34: =SUMIF(I:I,"德国股票粉（1）组【张小强】",J:J) -> 133280 | T34: 德国股票粉（1）组【张小强】
G35: 29 | H35: 45874 | I35: 印度15期 | J35: 22372 | K35: 15期补粉 | L35: 0.79861111 | M35: 印度企业户 欧洲美金户 | N35: 70.9 | O35: 60+10*1.09=70.9U | P35: 21：35 | S35: =SUMIF(I:I,"印度15期",J:J) -> 39144 | T35: 印度15期
G36: 30 | H36: 45875 | I36: 德国股票粉（1）组【张小强】 | J36: 800 | K36: 8月4日 德国股票粉（1）组【张小强】 8/4 X2有效2 8/4 M6有效1 8/4 J4有效2 合计: （2+1+2）*160=800 | L36: 0.56527778 | M36: GT&SHEN 欧洲户８＋１ 港60+5+1 | N36: 110 | O36: 100*1.1=110 | P36: 17：39 | S36: =SUMIF(I:I,"印度25期",J:J) -> 1928 | T36: 印度25期
G37: 31 | H37: 45875 | M37: GT&SHEN 欧洲户８＋１ 港60+5+1 | N37: 211.8 | O37: 60*3开户费+10*3*1.06=211.8 | P37: 0.76736111 | S37: =SUMIF(I:I,"波贝6期",J:J) -> 36232 | T37: 波贝6期
G38: 32 | H38: 45875 | M38: 广告配套 | N38: 243.62 | O38: 住宅Ip 120G | P38: 0.76944444 | S38: =SUMIF(I:I,"B1印度",J:J) -> 50000 | T38: B1印度
G39: 33 | H39: 45875 | M39: 深圳芳林子 | N39: 570.65 | O39: 500*1.13*1.01=570.65 | P39: 0.91805556 | S39: =SUMIF(I:I,"意大利第5梯队610",J:J) -> 7620 | T39: 意大利第5梯队610
G40: 34 | H40: 45875 | M40: 印度驻场-lala(郑总） | N40: 483 | P40: 22：04 | S40: =SUMIF(I:I,"印度16期",J:J) -> 30408 | T40: 印度16期
G41: 35 | H41: 45875 | I41: 印度25期 | J41: 1928 | L41: 11：37 | S41: =SUMIF(I:I,"渠道BF 德国F",J:J) -> 8000 | T41: 渠道BF 德国F
G42: 36 | H42: 45876 | I42: 钱包差值 | J42: 35.437 | S42: =SUMIF(I:I,"渠道L 英文L 马来",J:J) -> 18000 | T42: 渠道L 英文L 马来
...

Sheet 2025年7月收支财务报表
C1: 2025年7月收支财务报表
C4: 财务统计 STATISTICS | G4: 7月收支明细 DETAIL | S4: =SUMIF(M:M,"广告配套",N:N) -> 3174.84 | T4: U支出的广告配套（不含RMB支出）
G5: 序号 | H5: 日期 | I5: 收入 | M5: 支出
C6: 月份查询 | I6: 项目 | J6: 金额 | K6: 备注 | L6: 时间 | M6: 项目 | N6: 金额 | O6: 备注 | P6: 时间 | S6: =SUMIF(M:M,"后勤支出",N:N) -> 176614.67 | T6: 后勤支出
C7: 7月 | D7: ▼ | G7: 1 | H7: 45839 | I7: 6月结余 | J7: ='2025年6月收支财务报表'!C25 -> 138682.47 | S7: =SUMIF(M:M,"深圳芳林子",N:N) -> 339022.42 | T7: 深圳芳林子
C8: 收入 | G8: 2 | H8: 45839 | I8: 拉总（印度）24 | J8: 4656 | L8: 0.022222222 | M8: 深圳芳林子 | N8: 16915.53 | O8: 14193.26*1.18*1.01=16915.53 | P8: 0.60486111 | S8: =SUMIF(M:M,"印度企业户 欧洲美金户",N:N) -> 40671.09 | T8: 印度企业户 欧洲美金户
C9: =C21 -> 1512556.2 | G9: 3 | H9: 45839 | I9: 德国股票粉（2）组【张小强】 | J9: 2185.6 | K9: 6月29-6/30日 德国股票粉（2）组【张小强】 6/29 C2确认有效3.33个 6/30 C2确认有效4个 M1确认有效6.33个 合计: （3.33+10.33）*160=2185.6 | L9: 0.66458333 | S9: =SUMIF(M:M,"Nancy-印度户15➕1",N:N) -> 9511.52 | T9: Nancy-印度户15➕1
C10: 支出 | G10: 4 | H10: 45839 | I10: 印度12期 | J10: 50000 | L10: 0.66527778 | M10: 深圳芳林子 | N10: 1394.76 | O10: 1190.48*1.16*1.01=1394.76 | P10: 0.74583333 | S10: =SUMIF(M:M,"海总新渠道 10+1",N:N) -> 175152.61 | T10: 海总新渠道 10+1
C11: =C23 -> 1144021.9 | G11: 5 | H11: 45839 | M11: 印度企业户 欧洲美金户 | N11: 594.18 | O11: （1000-487.78）*1.16=594.18U | P11: 0.75486111 | S11: =SUMIF(M:M,"启航广告费",N:N) -> 18417.42 | T11: 启航广告费
C12: 结余 | G12: 6 | H12: 45839 | I12: 印度汤总 | J12: 28000 | L12: 0.87013889 | S12: =SUMIF(M:M,"十月二不限——（泰华）",N:N) -> 3034 | T12: 十月二不限——（泰华）
C13: =C9-C11 -> 368534.27 | G13: 7 | H13: 45839 | I13: 拉总（印度）24 | J13: 6240 | L13: 0.99166667 | S13: =SUMIF(M:M,"凤凰渠道-泰华",N:N) -> 168932.69 | T13: 凤凰渠道-泰华
G14: 8 | H14: 45840 | M14: 深圳芳林子 | N14: 2789.52 | O14: 200000/84*1.16*1.01=2789.52 | P14: 0.49722222 | S14: =SUMIF(M:M,"济宁韦宁&香港有意思 二不限 3%",N:N) -> 28902.08 | T14: 济宁韦宁&香港有意思 二不限 3%
C15: 任意时段查询 | G15: 9 | H15: 45840 | I15: 波贝3期 | J15: 50000 | L15: 0.56944444 | M15: 印度企业户 欧洲美金户 | N15: 1740 | O15: 1500*1.16=1740U | P15: 0.57847222 | S15: =SUMIF(M:M,"海总/户合作mom",N:N) -> 5750 | T15: 海总/户合作mom
C16: 起始日期： | G16: 10 | H16: 45840 | M16: 深圳芳林子 | N16: 47672 | O16: 40000*1.18*1.01=47672 | P16: 0.58055556 | S16: =SUMIF(M:M,"路人互动-海总（50-7）山",N:N) -> 5600 | T16: 路人互动-海总（50-7）山
C17: 45292 | G17: 11 | H17: 45840 | M17: Nancy-印度户15➕1 | N17: 9511.52 | O17: 8189*1.15*1.01=9511.52 | P17: 0.58402778 | S17: =SUMIF(M:M,"印度户印尼企业户",N:N) -> 62567.59 | T17: 印度户印尼企业户
C18: 结束日期： | G18: 12 | H18: 45840 | M18: 后勤支出 | N18: 62407.111 | O18: 6月分红- B哥138,682.47*0.45=62407.1115 | P18: 0.58611111 | S18: =SUMIF(M:M,"Y-5208 FB欧/美户",N:N) -> 1645 | T18: Y-5208 FB欧/美户
C19: 72805 | G19: 13 | H19: 45840 | I19: 德国蟑螂哥渠道 | J19: 480 | K19: 6/30 有效1，7/1 有效2 | L19: 15：09 | M19: 印度企业户 欧洲美金户 | N19: 3480 | O19: 3000*1.16=3480U | P19: 0.77916667 | S19: =SUMIF(M:M,"阿水 印度mom 11+1",N:N) -> 5600 | T19: 阿水 印度mom 11+1
C20: 收入 | G20: 14 | H20: 45840 | I20: 印度汤总 | J20: 28000 | L20: 0.89513889 | S20: =SUMIF(M:M,"波贝5期",N:N) -> 6116 | T20: 波贝5期
C21: =SUMIFS(J:J,H:H,">="&$C$17,H:H,"<="&$C$19) -> 1512556.2 | G21: 15 | H21: 45841 | M21: 深圳芳林子 | N21: 35422.58 | O21: 29721.92*1.18*1.01=35422.58 | P21: 0.57986111 | S21: =SUMIF(M:M,"波贝4期",N:N) -> 9328 | T21: 波贝4期
C22: 支出 | G22: 16 | H22: 45841 | I22: 拉总（印度）24 | J22: 1560 | L22: 0.61458333 | S22: =SUMIF(M:M,"预支",N:N) -> 50000 | T22: 预支
C23: =SUMIFS(N:N,H:H,">="&$C$17,H:H,"<="&$C$19) -> 1144021.9 | G23: 17 | H23: 45841 | I23: 印度12期 | J23: 50000 | L23: 0.63541667 | M23: 印度企业户 欧洲美金户 | N23: 11141.72 | O23: (10000-395.07)*1.16=11141.72 | P23: 0.6375 | S23: =SUMIF(M:M,"印度20期",N:N) -> 15540 | T23: 印度20期
C24: 结余 | G24: 18 | H24: 45841 | M24: 深圳芳林子 | N24: 11918 | O24: 10000*1.18*1.01=11918 | P24: 0.64513889 | S24: =SUMIF(M:M,"渠道BF 德国B",N:N) -> 4290 | T24: 渠道BF 德国B
C25: =C21-C23 -> 368534.27 | G25: 19 | H25: 45841 | I25: 德国股票粉（2）组【张小强】 | J25: 2025.6 | K25: 7月1-2日 德国股票粉（2）组【张小强】 7/1 T3确认有效7.66个 K4确认有效1个 7/2 F6确认有效4 合计: （8.66+4）*160=2025.6 | L25: 0.64861111 | S25: =SUMIF(M:M,"波贝3期",N:N) -> 14152 | T25: 波贝3期
G26: 20 | H26: 45841 | I26: 印度汤总 | J26: 42000 | L26: 0.88958333 | S26: =SUM(S4:S25) -> 1144021.9
G27: 21 | H27: 45842 | I27: 拉总（印度）24 | J27: 4800 | L27: 0.0069444444 | M27: 印度企业户 欧洲美金户 | N27: 8050 | O27: 7000*1.15=8050U | P27: 0.57569444
G28: 22 | H28: 45842 | M28: 深圳芳林子 | N28: 7251.8 | O28: (1000*1.13+150+5000*1.18)*1.01=7251.8 | P28: 0.58611111 | S28: 往上支出-------------------分割线-------------------往下收入
G29: 23 | H29: 45842 | M29: 印度企业户 欧洲美金户 | N29: 1150 | O29: 1000*1.15=1150U | P29: 0.63194444
G30: 24 | H30: 45842 | M30: 海总新渠道 10+1 | N30: 2260 | O30: 2000*1.13=2260 | P30: 0.66805556 | S30: =SUMIF(I:I,"拉总（印度）24",J:J) -> 41040 | T30: 拉总（印度）24
G31: 25 | H31: 45842 | I31: Nancy-印度户15➕1 | J31: 11323.12 | L31: 0.68125 | M31: 启航广告费 | N31: 2087.72 | O31: 6/7-7/4 : 4100+544.45-2556.73=2087.72 | P31: 0.7375 | S31: =SUMIF(I:I,"德国股票粉（2）组【张小强】",J:J) -> 4371.2 | T31: 德国股票粉（2）组【张小强】
G32: 26 | H32: 45842 | M32: 海总新渠道 10+1 | N32: 1130 | O32: 1000*1.13=1130 | P32: 0.78402778 | S32: =SUMIF(I:I,"德国股票粉（3）组【张小强】",J:J) -> 68904 | T32: 德国股票粉（3）组【张小强】
G33: 27 | H33: 45842 | I33: 波贝3期 | J33: 50000 | L33: 0.82013889 | S33: =SUMIF(I:I,"印度12期",J:J) -> 100000 | T33: 印度12期
G34: 28 | H34: 45842 | I34: 印度汤总 | J34: 12488 | L34: 0.95347222 | S34: =SUMIF(I:I,"印度13期",J:J) -> 50000 | T34: 印度13期
G35: 29 | H35: 45842 | I35: 拉总（印度）24 | J35: 8184 | L35: 0.98541667 | S35: =SUMIF(I:I,"印度14期",J:J) -> 50000 | T35: 印度14期
G36: 30 | H36: 45843 | M36: 后勤支出 | N36: 8147.0055 | O36: 发工资 | P36: 0.62708333 | S36: =SUMIF(I:I,"印度15期",J:J) -> 129228 | T36: 印度15期
G37: 31 | H37: 45843 | M37: 后勤支出 | N37: 7389.3272 | O37: 发工资 | P37: 0.62847222 | S37: =SUMIF(I:I,"印度汤总",J:J) -> 110488 | T37: 印度汤总
G38: 32 | H38: 45843 | M38: 后勤支出 | N38: 6170.5728 | O38: 发工资 | P38: 0.62986111 | S38: =SUMIF(I:I,"波贝3期",J:J) -> 100000 | T38: 波贝3期
G39: 33 | H39: 45843 | M39: 后勤支出 | N39: 675.38028 | O39: 发工资 | P39: 0.63125 | S39: =SUMIF(I:I,"波贝4期",J:J) -> 150000 | T39: 波贝4期
G40: 34 | H40: 45843 | M40: 后勤支出 | N40: 2657.5775 | O40: 发工资 | P40: 0.63263889 | S40: =SUMIF(I:I,"德国蟑螂哥渠道",J:J) -> 18400 | T40: 德国蟑螂哥渠道
G41: 35 | H41: 45843 | M41: 后勤支出 | N41: 816.90141 | O41: 发工资 | P41: 0.63333333 | S41: =SUMIF(I:I,"印度20期",J:J) -> 100800 | T41: 印度20期
G42: 36 | H42: 45843 | M42: 后勤支出 | N42: 4684.6175 | O42: 发工资 | P42: 0.63472222 | S42: =SUMIF(I:I,"印度21期",J:J) -> 50000 | T42: 印度21期
...

Sheet 2025年6月收支财务报表
C1: 2025年6月收支财务报表
C4: 财务统计 STATISTICS | G4: 6月收支明细 DETAIL | S4: =SUMIF(M:M,"广告配套",N:N) -> 2479.45 | T4: U支出的广告配套（不含RMB支出）
G5: 序号 | H5: 日期 | I5: 收入 | M5: 支出
C6: 月份查询 | I6: 项目 | J6: 金额 | K6: 备注 | L6: 时间 | M6: 项目 | N6: 金额 | O6: 备注 | P6: 时间 | S6: =SUMIF(M:M,"后勤支出",N:N) -> 462600.09 | T6: 后勤支出
C7: 6月 | D7: ▼ | G7: 1 | H7: 45809 | I7: 5月结余 | J7: ='2025年5月收支财务报表'!C13 -> 396123 | S7: =SUMIF(M:M,"深圳芳林子",N:N) -> 314138.57 | T7: 深圳芳林子
C8: 收入 | G8: 2 | H8: 45809 | I8: 白马2期 | J8: 30800 | L8: 0.65972222 | S8: =SUMIF(M:M,"海总-MC开户对接群（果果）",N:N) -> 6711.28 | T8: 海总-MC开户对接群（果果）
C9: =C21 -> 965658.5 | G9: 3 | H9: 45809 | I9: 德国 张总（王总） | J9: 2295 | K9: 5月29-31日 德国 张总（王总） 5/29 有效5 5/30 有效3 5/31 有效9 合计：(5+3+9)*135=2295 | L9: 0.66875 | S9: =SUMIF(M:M,"十月二不限——（泰华）",N:N) -> 13192.75 | T9: 十月二不限——（泰华）
C10: 支出 | G10: 4 | H10: 45809 | I10: 拉总（印度）24 | J10: 5856 | L10: 0.94236111 | S10: =SUMIF(M:M,"印度企业户 欧洲美金户",N:N) -> 4743.13 | T10: 印度企业户 欧洲美金户
C11: =C23 -> 826976.03 | G11: 5 | H11: 45810 | M11: 后勤支出 | N11: 178255.35 | O11: 5月分红- B哥396,123.00 *0.45=178255.35 | P11: 0.42152778 | S11: =SUMIF(M:M,"凤凰渠道-泰华",N:N) -> 3896.76 | T11: 凤凰渠道-泰华
C12: 结余 | G12: 6 | H12: 45810 | M12: 深圳芳林子 | N12: 3945.99 | O12: 15000-11448.25=3551.75*1.1*1.01=3945.99 | P12: 0.48958333 | S12: =SUMIF(M:M,"泰华&ME-FB海外户对接群",N:N) -> 3603.2 | T12: 泰华&ME-FB海外户对接群
C13: =C9-C11 -> 138682.47 | G13: 7 | H13: 45810 | I13: 白马3期 | J13: 50400 | L13: 0.60625 | S13: =SUMIF(M:M,"黑泽-欧洲户对接",N:N) -> 2505.8 | T13: 黑泽-欧洲户对接
G14: 8 | H14: 45811 | M14: 广告配套 | N14: 208.21 | O14: 耐用号*5 | P14: 0.44583333 | S14: =SUMIF(M:M,"开户美国三不限户",N:N) -> 1170 | T14: 开户美国三不限户
C15: 任意时段查询 | G15: 9 | H15: 45811 | M15: 深圳芳林子 | N15: 16665 | O15: 15000*1.1*1.01=16665 | P15: 0.4625 | S15: =SUMIF(M:M,"济宁韦宁&香港有意思 二不限 3%",N:N) -> 520 | T15: 济宁韦宁&香港有意思 二不限 3%
C16: 起始日期： | G16: 10 | H16: 45811 | I16: 白马2期 | J16: 31444 | K16: 尾款 | L16: 0.59513889 | S16: =SUMIF(M:M,"海总新渠道 10+1",N:N) -> 1110 | T16: 海总新渠道 10+1
C17: 45292 | G17: 11 | H17: 45811 | I17: 拉总（印度）24 | J17: 840 | L17: 14.31 | S17: =SUMIF(M:M,"ALEX&西班牙",N:N) -> 1275 | T17: ALEX&西班牙
C18: 结束日期： | G18: 12 | H18: 45811 | I18: 德国 张总（王总） | J18: 405 | K18: 6/2 有效3 合计：3*135=405 | L18: 0.70625 | M18: 深圳芳林子 | N18: 11204.01 | O18: （10000-853.32）*1.1918+开户费150*2*1.01=11204.01 | P18: 0.70625 | S18: =SUMIF(M:M,"老傅渠道",N:N) -> 6630 | T18: 老傅渠道
C19: 72805 | G19: 13 | H19: 45811 | I19: 渠道BF 德国B | J19: 6500 | L19: 0.92916667 | S19: =SUMIF(M:M,"印度006对接—henry",N:N) -> 2400 | T19: 印度006对接—henry
C20: 收入 | G20: 14 | H20: 45812 | M20: 深圳芳林子 | N20: 16665 | O20: 15000*1.1*1.01=16665 | P20: 0.45416667 | S20: =SUM(S4:S19) -> 826976.03
C21: =SUMIFS(J:J,H:H,">="&$C$17,H:H,"<="&$C$19) -> 965658.5 | G21: 15 | H21: 45812 | M21: 海总-MC开户对接群（果果） | N21: 505 | O21: 500*1.01=505 | P21: 16：29
C22: 支出 | G22: 16 | H22: 45812 | M22: 十月二不限——（泰华） | N22: 838.89 | O22: (1400-611)*1.01+42=838.89 | P22: 0.88819444 | S22: 往上支出-------------------分割线-------------------往下收入
C23: =SUMIFS(N:N,H:H,">="&$C$17,H:H,"<="&$C$19) -> 826976.03 | G23: 17 | H23: 45813 | I23: 海哥-奥地利 | J23: 270 | L23: 0.55694444 | M23: 印度企业户 欧洲美金户 | N23: 560 | O23: 500*1.12=560U | P23: 0.58958333
C24: 结余 | G24: 18 | H24: 45813 | M24: 后勤支出 | N24: 13932.313 | O24: 发工资 | P24: 0.60763889 | S24: =SUMIF(I:I,"白马2期",J:J) -> 97636 | T24: 白马2期
C25: =C21-C23 -> 138682.47 | G25: 19 | H25: 45813 | M25: 后勤支出 | N25: 8083.98 | O25: 发工资 | P25: 0.60972222 | S25: =SUMIF(I:I,"德国 张总（王总）",J:J) -> 2700 | T25: 德国 张总（王总）
G26: 20 | H26: 45813 | M26: 后勤支出 | N26: 9207.0789 | O26: 发工资 | P26: 0.60972222 | S26: =SUMIF(I:I,"拉总（印度）24",J:J) -> 114504 | T26: 拉总（印度）24
G27: 21 | H27: 45813 | M27: 后勤支出 | N27: 778.36637 | O27: 发工资 | P27: 0.61180556 | S27: =SUMIF(I:I,"白马3期",J:J) -> 166292 | T27: 白马3期
G28: 22 | H28: 45813 | M28: 后勤支出 | N28: 8531.9161 | O28: 发工资 | P28: 0.61319444 | S28: =SUMIF(I:I,"渠道BF 德国B",J:J) -> 6500 | T28: 渠道BF 德国B
G29: 23 | H29: 45813 | M29: 后勤支出 | N29: 910.9009 | O29: 发工资 | P29: 0.61458333 | S29: =SUMIF(I:I,"海哥-奥地利",J:J) -> 3870 | T29: 海哥-奥地利
G30: 24 | H30: 45813 | M30: 后勤支出 | N30: 7253.8711 | O30: 发工资 | P30: 0.61597222 | S30: =SUMIF(I:I,"印度十期",J:J) -> 50000 | T30: 印度十期
G31: 25 | H31: 45813 | M31: 后勤支出 | N31: 667.55556 | O31: 发工资 | P31: 0.61666667 | S31: =SUMIF(I:I,"印度11期",J:J) -> 100000 | T31: 印度11期
G32: 26 | H32: 45813 | M32: 后勤支出 | N32: 555.55556 | O32: 发工资 | P32: 0.61736111 | S32: =SUMIF(I:I,"蟑螂哥西班牙渠道（3梯队）",J:J) -> 100 | T32: 蟑螂哥西班牙渠道（3梯队）
G33: 27 | H33: 45813 | M33: 后勤支出 | N33: 555.55556 | O33: 发工资 | P33: 0.61805556 | S33: =SUMIF(I:I,"德国股票粉（2）组【张小强】",J:J) -> 13549.5 | T33: 德国股票粉（2）组【张小强】
G34: 28 | H34: 45813 | M34: 后勤支出 | N34: 1000 | O34: 发工资 | P34: 0.61944444 | S34: =SUMIF(I:I,"ALEX&西班牙",J:J) -> 1700 | T34: ALEX&西班牙
G35: 29 | H35: 45813 | M35: 后勤支出 | N35: 5000 | O35: 发工资 | P35: 0.62013889 | S35: =SUMIF(I:I,"德国蟑螂哥渠道",J:J) -> 8700 | T35: 德国蟑螂哥渠道
G36: 30 | H36: 45813 | M36: 后勤支出 | N36: 39612.3 | O36: 5月分红- LH，396,123.00*10%=39612.3 | P36: 0.62638889 | S36: =SUMIF(I:I,"GT海总欧洲金融户20+9+1",J:J) -> 424 | T36: GT海总欧洲金融户20+9+1
G37: 31 | H37: 45813 | M37: 十月二不限——（泰华） | N37: 1031 | O37: 1000*1.01+21=1031 | P37: 0.94513889 | S37: =SUMIF(I:I,"GT-HY&papa 二不限",J:J) -> 1360 | T37: GT-HY&papa 二不限
G38: 32 | H38: 45814 | M38: 广告配套 | N38: 36 | O38: BM*10 | P38: 0.50347222 | S38: =SUMIF(I:I,"老傅渠道",J:J) -> 2200 | T38: 老傅渠道
G39: 33 | H39: 45814 | I39: 海哥-奥地利 | J39: 270 | L39: 0.51319444 | M39: 深圳芳林子 | N39: 16210.02 | O39: (15000-409.52)*1.1*1.01=16210.02 | P39: 0.56736111 | S39: =J7 -> 396123 | T39: 5月结余
G40: 34 | H40: 45814 | M40: 印度企业户 欧洲美金户 | N40: 560 | O40: 500*1.12=560U | P40: 0.91319444 | S40: =SUM(S24:S39) -> 965658.5
G41: 35 | H41: 45814 | M41: 凤凰渠道-泰华 | N41: 1911 | O41: （5000-3938.24）+530+320=1911.76 | P41: 0.91458333
G42: 36 | H42: 45815 | I42: 拉总（印度）24 | J42: 11040 | L42: 0.55972222
...

Sheet 2025年5月收支财务报表
C1: 2025年5月收支财务报表
C4: 财务统计 STATISTICS | G4: 5月收支明细 DETAIL | S4: =SUMIF(M:M,"广告配套",N:N) -> 3004.2273 | T4: U支出的广告配套（不含RMB支出）
G5: 序号 | H5: 日期 | I5: 收入 | M5: 支出
C6: 月份查询 | I6: 项目 | J6: 金额 | K6: 备注 | L6: 时间 | M6: 项目 | N6: 金额 | O6: 备注 | P6: 时间 | S6: =SUMIF(M:M,"后勤支出",N:N) -> 160029.02 | T6: 后勤支出
C7: 5月 | D7: ▼ | G7: 1 | H7: 45778 | I7: 4月结余 | J7: ='2025年4月收支财务报表'!C13 -> 234903.21 | M7: 深圳芳林子 | N7: 19998 | O7: 18000*1.1*1.01=19998 | P7: 0.45347222 | S7: =SUMIF(M:M,"深圳芳林子",N:N) -> 615726.92 | T7: 深圳芳林子
C8: 收入 | G8: 2 | H8: 45778 | M8: 深圳芳林子 | N8: 5555 | O8: 5000*1.1*1.01=5555 | P8: 0.48819444 | S8: =SUMIF(M:M,"十月二不限——（泰华）",N:N) -> 15197.11 | T8: 十月二不限——（泰华）
C9: =C21 -> 1361013.5 | G9: 3 | H9: 45778 | M9: 广告配套 | N9: 500 | O9: 矿工费TRX | P9: 0.63958333 | S9: =SUMIF(M:M,"印度企业户 欧洲美金户",N:N) -> 27871 | T9: 印度企业户 欧洲美金户
C10: 支出 | G10: 4 | H10: 45778 | M10: 意大利（海哥） | N10: 10 | P10: 0.69166667 | S10: =SUMIF(M:M,"Y-5208 FB欧/美户",N:N) -> 3986.8 | T10: Y-5208 FB欧/美户
C11: =C23 -> 964890.53 | G11: 5 | H11: 45778 | M11: 意大利（海哥） | N11: =21000-N10 -> 20990 | O11: 30000-75*120=21000（退款） | P11: 0.7 | S11: =SUMIF(M:M,"海总-MC开户对接群（果果）",N:N) -> 9923.28 | T11: 海总-MC开户对接群（果果）
C12: 结余 | G12: 6 | H12: 45778 | M12: 十月二不限——（泰华） | N12: 1435 | P12: 0.71111111 | S12: =SUMIF(M:M,"海总-黑泽-欧洲户对接",N:N) -> 3983.33 | T12: 海总-黑泽-欧洲户对接
C13: =C9-C11 -> 396123 | G13: 7 | H13: 45778 | I13: 德国 张总（王总） | J13: 3915 | K13: 4月30日 德国 张总（王总） 4/30 德国单导 有效26 4/30 H1 有效3 合计：(26+3)*135=3915 | L13: 0.81875 | M13: 广告配套 | N13: 34 | O13: 开电报会员一年测试 | P13: 0.81944444 | S13: =SUMIF(M:M,"启航广告费",N:N) -> 4545.64 | T13: 启航广告费
G14: 8 | H14: 45778 | M14: 广告配套 | N14: 282 | O14: IP+ws计数号 | P14: 0.83402778 | S14: =SUMIF(M:M,"泰华&ME-FB海外户对接群-Mark",N:N) -> 1385 | T14: 泰华&ME-FB海外户对接群-Mark
C15: 任意时段查询 | G15: 9 | H15: 45778 | M15: 十月二不限——（泰华） | N15: 1010 | P15: 0.99652778 | S15: =SUMIF(M:M,"Nancy-印度户15➕1",N:N) -> 20642.2 | T15: Nancy-印度户15➕1
C16: 起始日期： | G16: 10 | H16: 45779 | M16: 老傅渠道 | N16: 8470 | P16: 0.00069444444 | S16: =SUMIF(M:M,"T86 共享额度户P6",N:N) -> 1100 | T16: T86 共享额度户P6
C17: 45292 | G17: 11 | H17: 45779 | M17: 印度企业户 欧洲美金户 | N17: 11110 | O17: 10000*1.11=11100U，转多了10U | P17: 0.44236111
C18: 结束日期： | G18: 12 | H18: 45779 | M18: 深圳芳林子 | N18: 8888 | O18: 8000*1.1*1.01=8888 | P18: 0.45347222
C19: 72805 | G19: 13 | H19: 45779 | M19: Y-5208 FB欧/美户 | N19: 3270 | O19: 3000×1.09=3270 | P19: 0.61597222
C20: 收入 | G20: 14 | H20: 45779 | I20: 印度6期 | J20: 36824 | K20: 尾款 | L20: 0.65347222 | S20: =SUMIF(M:M,"意大利（海哥）",N:N) -> 21000 | T20: 意大利（海哥） | U20: 退款
C21: =SUMIFS(J:J,H:H,">="&$C$17,H:H,"<="&$C$19) -> 1361013.5 | G21: 15 | H21: 45779 | I21: 德国 张总（王总） | J21: 6210 | K21: 5.1 德国单导 4915215411390 7 4915213020236 5 4915217743336 12 4915219367517 5 4915212897643 5 4915210591435 7 4915510564480 5 共计46 合计：46*135=6210 | L21: 0.87569444 | M21: 后勤支出 | N21: 52310.7 | O21: 4月分红- B哥116,246*0.45=52310.7 | P21: 0.91666667 | S21: =SUMIF(M:M,"渠道F 马来K",N:N) -> 130 | T21: 渠道F 马来K | U21: 退款
C22: 支出 | G22: 16 | H22: 45779 | M22: 十月二不限——（泰华） | N22: 947.38 | O22: 900-162=738*1.01=745.38+202=947.38 | P22: 0.99791667 | S22: =SUMIF(M:M,"印度006对接—henry",N:N) -> 759 | T22: 印度006对接—henry
C23: =SUMIFS(N:N,H:H,">="&$C$17,H:H,"<="&$C$19) -> 964890.53 | G23: 17 | H23: 45780 | M23: 深圳芳林子 | N23: 25118.7 | O23: 21000*1.1*1.01=23331，1500*1.18*1.01=1787.7，合计：25118.7 | P23: 0.42916667 | S23: =SUMIF(M:M,"印度驻场-lala(郑总）",N:N) -> 3887 | T23: 印度驻场-lala(郑总）
C24: 结余 | G24: 18 | H24: 45780 | M24: 印度企业户 欧洲美金户 | N24: 6650 | O24: 6000*1.11=6660-10=6650U | P24: 0.52361111 | S24: =SUMIF(M:M,"日本001对接_Chirs",N:N) -> 24420 | T24: 日本001对接_Chirs
C25: =C21-C23 -> 396123 | G25: 19 | H25: 45780 | I25: 德国 张总（王总） | J25: 10395 | K25: 5月2日 德国 张总（王总） 5/2 德国单导 4915215411390 5 4915213020236 5 4915217743336 5 4915219367517 3 4915212897643 2 4915210678752 6 4915210276617 5 4915210756851 6 4915217927758 5 4915217743410 2 4915213086520 6 4915212392118 1 4917686639880 5 4915510461712 5 4915210797499 5 4917673986846 5 4915510564480 6 4915210746583 0 总 77 合计：77*135=10395 | L25: 0.85 | S25: =SUMIF(M:M,"老傅渠道",N:N) -> 47300 | T25: 老傅渠道
G26: 20 | H26: 45781 | M26: 深圳芳林子 | N26: 27775 | O26: 25000*1.1*1.01=27775 | P26: 0.45833333 | S26: =SUM(S4:S25) -> 964890.53
G27: 21 | H27: 45782 | I27: 印度7期 | J27: 50000 | L27: 0.79166667
G28: 22 | H28: 45782 | M28: 印度企业户 欧洲美金户 | N28: 6216 | O28: 5600*1.11=6216U | P28: 0.43958333 | S28: 往上支出-------------------分割线-------------------往下收入
G29: 23 | H29: 45782 | M29: 深圳芳林子 | N29: 23331 | O29: (17500+3500)*1.10*1.01=23331 | P29: 0.44027778
G30: 24 | H30: 45782 | M30: 老傅渠道 | N30: 10670 | P30: 0.59027778 | S30: =SUMIF(I:I,"德国 张总（王总）",J:J) -> 38880 | T30: 德国 张总（王总）
G31: 25 | H31: 45782 | M31: 后勤支出 | N31: 9845.852 | O31: 发工资 | P31: 0.64375 | S31: =SUMIF(I:I,"印度6期",J:J) -> 36824 | T31: 印度6期
G32: 26 | H32: 45782 | M32: 后勤支出 | N32: 3428.2577 | O32: 发工资 | P32: 0.64583333 | S32: =SUMIF(I:I,"印度7期",J:J) -> 130000 | T32: 印度7期
G33: 27 | H33: 45782 | M33: 后勤支出 | N33: 2774.057 | O33: 发工资 | P33: 0.64652778 | S33: =SUMIF(I:I,"渠道30 日股粉（张总） 谷歌",J:J) -> 28000 | T33: 渠道30 日股粉（张总） 谷歌
G34: 28 | H34: 45782 | M34: 后勤支出 | N34: 689.81987 | O34: 发工资 | P34: 0.64861111 | S34: =SUMIF(I:I,"印度15期",J:J) -> 7680 | T34: 印度15期
G35: 29 | H35: 45782 | M35: 后勤支出 | N35: 4647.3647 | O35: 发工资 | P35: 0.65 | S35: =SUMIF(I:I,"德国股票粉3组【张小强】",J:J) -> 29025 | T35: 德国股票粉3组【张小强】
G36: 30 | H36: 45782 | M36: 后勤支出 | N36: 889.58003 | O36: 发工资 | P36: 0.65138889 | S36: =SUMIF(I:I,"德国股票粉4组【张小强】",J:J) -> 5714 | T36: 德国股票粉4组【张小强】
G37: 31 | H37: 45782 | M37: 后勤支出 | N37: 3181.2574 | O37: 发工资 | P37: 0.65277778 | S37: =SUMIF(I:I,"印度8期",J:J) -> 202256 | T37: 印度8期
G38: 32 | H38: 45782 | M38: 后勤支出 | N38: 914.5071 | O38: 发工资 | P38: 0.65416667 | S38: =SUMIF(I:I,"印度B1",J:J) -> 23576 | T38: 印度B1
G39: 33 | H39: 45782 | M39: 后勤支出 | N39: 567.85952 | O39: 发工资 | P39: 0.65486111 | S39: =SUMIF(I:I,"印度BB1",J:J) -> 91756 | T39: 印度BB1
G40: 34 | H40: 45782 | M40: 后勤支出 | N40: 566.68771 | O40: 发工资 | P40: 0.65625 | S40: =SUMIF(I:I,"渠道F 马来K",J:J) -> 6500 | T40: 渠道F 马来K
G41: 35 | H41: 45782 | M41: 后勤支出 | N41: 1000 | O41: 发工资 | P41: 0.65902778 | S41: =SUMIF(I:I,"印度9期",J:J) -> 313056 | T41: 印度9期
G42: 36 | H42: 45782 | M42: 后勤支出 | N42: 5277.7778 | O42: 发工资 | P42: 0.65972222 | S42: =SUMIF(I:I,"波贝2期",J:J) -> 124572 | T42: 波贝2期
...

Sheet 2025年4月收支财务报表
C1: 2025年4月收支财务报表
C4: 财务统计 STATISTICS | G4: 2025年4月收支明细 DETAIL | S4: =SUMIF(M:M,"广告配套",N:N) -> 3018.52 | T4: U支出的广告配套（不含RMB支出）
G5: 序号 | H5: 日期 | I5: 收入 | M5: 支出
C6: 月份查询 | I6: 项目 | J6: 金额 | K6: 备注 | L6: 时间 | M6: 项目 | N6: 金额 | O6: 备注 | P6: 时间 | S6: =SUMIF(M:M,"后勤支出",N:N) -> 259984.87 | T6: 后勤支出
C7: 4月 | D7: ▼ | G7: 1 | H7: 45748 | I7: 3月结余 | J7: ='2025年3月收支财务报表'!C13 -> 323365.14 | M7: 海总-黑泽-欧洲户对接 | N7: 545.4 | O7: 500*1.08*1.01=545.4 | P7: 0.48333333 | S7: =SUMIF(M:M,"海总-黑泽-欧洲户对接",N:N) -> 4543.2 | T7: 海总-黑泽-欧洲户对接
C8: 收入 | G8: 2 | H8: 45748 | I8: 渠道30 日股粉（张总） FB | J8: 100 | L8: 0.4875 | S8: =SUMIF(M:M,"海总- BM户对接",N:N) -> 530 | T8: 海总- BM户对接
C9: =C21 -> 1286870.5 | G9: 3 | H9: 45748 | I9: 渠道30 日股粉（张总） FB | J9: 17900 | K9: 预付100个 | L9: 0.49305556 | M9: 大表哥 FB&意大利 | N9: 10 | P9: 0.57777778 | S9: =SUMIF(M:M,"海总-全球户",N:N) -> 3260 | T9: 海总-全球户
C10: 支出 | G10: 4 | H10: 45748 | M10: 大表哥 FB&意大利 | N10: =1400-N9 -> 1390 | P10: 0.57847222 | S10: =SUMIF(M:M,"深圳芳林子",N:N) -> 320642.63 | T10: 深圳芳林子
C11: =C23 -> 1051967.3 | G11: 5 | H11: 45748 | M11: 海总-黑泽-欧洲户对接 | N11: 545.4 | O11: 500*1.08*1.01=545.4 | P11: 0.59722222 | S11: =SUMIF(M:M,"Y-5208 FB欧/美户",N:N) -> 12009.9 | T11: Y-5208 FB欧/美户
C12: 结余 | G12: 6 | H12: 45748 | M12: 大表哥 FB&意大利 | N12: 3000 | P12: 0.65208333 | S12: =SUMIF(M:M,"十月二不限——（泰华）",N:N) -> 9282 | T12: 十月二不限——（泰华）
C13: =C9-C11 -> 234903.21 | G13: 7 | H13: 45748 | M13: 海总- BM户对接 | N13: 530 | O13: -500*1.06=-530 | P13: 0.67222222 | S13: =SUMIF(M:M,"启航广告费",N:N) -> 1268.25 | T13: 启航广告费
G14: 8 | H14: 45748 | I14: 印度13期 | J14: 11172 | K14: 28*399=11172 | L14: 0.76666667 | M14: 广告配套 | N14: 13 | O14: 6个主页 | P14: 0.83333333 | S14: =SUMIF(M:M,"账单户充值",N:N) -> 9003.62 | T14: 账单户充值
C15: 任意时段查询 | G15: 9 | H15: 45749 | M15: 浩天 意大利对接群 | N15: 1300 | P15: 0.56597222 | S15: =SUMIF(M:M,"印度企业户 欧洲美金户",N:N) -> 78938.92 | T15: 印度企业户 欧洲美金户
C16: 起始日期： | G16: 10 | H16: 45749 | M16: 印度003对接—胖鱼 | N16: 4301 | P16: 0.57222222 | S16: =SUMIF(M:M,"CH加白户14➕1-Nancy",N:N) -> 48788.5 | T16: CH加白户14➕1-Nancy
C17: 45292 | G17: 11 | H17: 45749 | M17: 后勤支出 | N17: 100514.32 | O17: 3月分红- B哥 | P17: 0.60763889 | S17: =SUMIF(M:M,"HY&papa 二不限",N:N) -> 3814.28 | T17: HY&papa 二不限
C18: 结束日期： | G18: 12 | H18: 45749 | M18: 海总-全球户 | N18: 270 | P18: 0.63333333 | S18: =SUMIF(M:M,"MY &Shen SSS户 70+13%U1",N:N) -> 3101.6 | T18: ZJL&Shen 印度企业户 15+1/MY &Shen SSS户 70+13%U1
C19: 72805 | G19: 13 | H19: 45749 | M19: 海总-德国🇩🇪粉 | N19: 10 | P19: 0.64722222 | S19: =SUMIF(M:M,"R9GT&SHEN 欧 ",N:N) -> 1090 | T19: R9GT&SHEN 欧
C20: 收入 | G20: 14 | H20: 45749 | M20: 海总-德国🇩🇪粉 | N20: =1400-N19 -> 1390 | P20: 0.66180556 | S20: =SUMIF(M:M,"Andy- 美金谷歌户25+5%",N:N) -> 321 | T20: Andy- 美金谷歌户25+5%
C21: =SUMIFS(J:J,H:H,">="&$C$17,H:H,"<="&$C$19) -> 1286870.5 | G21: 15 | H21: 45749 | M21: 海总-黑泽-欧洲户对接 | N21: 120 | O21: 开户费 | P21: 0.71111111 | S21: =SUMIF(M:M,"欧洲户&hz唐",N:N) -> 2520 | T21: 欧洲户&hz唐
C22: 支出 | G22: 16 | H22: 45749 | M22: 广告配套 | N22: 31 | O22: 动态IP2个、计数号*2 | P22: 0.81180556 | S22: =SUMIF(M:M,"凤凰渠道-泰华",N:N) -> 2474 | T22: 凤凰渠道-泰华
C23: =SUMIFS(N:N,H:H,">="&$C$17,H:H,"<="&$C$19) -> 1051967.3 | G23: 17 | H23: 45749 | M23: 浩天 意大利对接群 | N23: 3000 | P23: 0.86180556 | S23: =SUMIF(M:M,"钱包转款小额测试",N:N) -> 10 | T23: 钱包转款小额测试
C24: 结余 | G24: 18 | H24: 45749 | I24: 印度4期-啊光 | J24: 50000 | L24: 0.94097222 | S24: =SUMIF(M:M,"大表哥 FB&意大利",N:N) -> 17100 | T24: 大表哥 FB&意大利
C25: =C21-C23 -> 234903.21 | G25: 19 | H25: 45750 | M25: 老傅渠道 | N25: 5360 | P25: 0.56388889 | S25: =SUMIF(M:M,"浩天 意大利对接群",N:N) -> 19200 | T25: 浩天 意大利对接群
G26: 20 | H26: 45750 | M26: 海总-🌙日本🇯🇵-岳 | N26: 10 | P26: 0.56597222 | S26: =SUMIF(M:M,"海总-德国🇩🇪粉",N:N) -> 7900 | T26: 海总-德国🇩🇪粉
G27: 21 | H27: 45750 | M27: 海总-🌙日本🇯🇵-岳 | N27: =4800-N26 -> 4790 | P27: 0.56666667 | S27: =SUMIF(M:M,"老傅渠道",N:N) -> 118680 | T27: 老傅渠道
G28: 22 | H28: 45750 | M28: 广告配套 | N28: 270 | O28: IP*30 | P28: 0.56944444 | S28: =SUMIF(M:M,"海总-🌙日本🇯🇵-岳",N:N) -> 19072 | T28: 海总-🌙日本🇯🇵-岳
G29: 23 | H29: 45750 | M29: 广告配套 | N29: 15 | O29: 7个主页 | P29: 0.58402778 | S29: =SUMIF(M:M,"印度003对接—胖鱼",N:N) -> 5014 | T29: 印度003对接—胖鱼
G30: 24 | H30: 45750 | M30: 深圳芳林子 | N30: 2686.6 | O30: 150*2*1.01+2000*1.18*1.01=2686.6 | P30: 0.65694444 | S30: =SUMIF(M:M,"印度驻场-lala(郑总）",N:N) -> 17411 | T30: 印度驻场-lala(郑总）
G31: 25 | H31: 45750 | M31: 印度驻场-lala(郑总） | N31: 6532 | P31: 0.67361111 | S31: =SUMIF(M:M,"印度006对接—henry",N:N) -> 5543 | T31: 印度006对接—henry
G32: 26 | H32: 45750 | M32: 浩天 意大利对接群 | N32: 3400 | P32: 0.68888889 | S32: =SUMIF(M:M,"渠道30 日股粉（张总） FB",N:N) -> 52740 | T32: 渠道30 日股粉（张总） FB退款 | U32: 4/21已退
G33: 27 | H33: 45750 | M33: 广告配套 | N33: 20 | O33: 9个主页 | P33: 0.88333333 | S33: =SUMIF(M:M,"德国股民单粉——summer",N:N) -> 12150 | T33: 德国股民单粉——summer退款 | U33: 4/10已退
G34: 28 | H34: 45751 | I34: 渠道30 日股粉（张总） FB | J34: 9000 | K34: 预付50个 | L34: 0.50555556 | M34: 浩天 意大利对接群 | N34: 3000 | P34: 0.64097222 | S34: =SUMIF(M:M,"海哥一期（印度1500）",N:N) -> 12556 | T34: 海哥一期（印度1500） | U34: 4/26已退
G35: 29 | H35: 45751 | M35: 老傅渠道 | N35: 8640 | P35: 0.84722222 | S35: 往上支出-------------------分割线-------------------往下收入
G36: 30 | H36: 45751 | I36: 意大利（海哥） | J36: 30000 | L36: 0.98263889 | S36: =SUM(S4:S34) -> 1051967.3
G37: 31 | H37: 45752 | M37: 后勤支出 | N37: 22336.515 | O37: 3月分红- LH | P37: 0.60069444
G38: 32 | H38: 45752 | M38: 后勤支出 | N38: 5096.5079 | O38: 发工资 | P38: 0.62916667 | S38: =SUMIF(I:I,"海总-🌙日本🇯🇵-岳",J:J) -> 7936 | T38: 海总-🌙日本🇯🇵-岳
G39: 33 | H39: 45752 | M39: 后勤支出 | N39: 3489.2132 | O39: 发工资 | P39: 0.63194444 | S39: =SUMIF(I:I,"浩天 意大利对接群",J:J) -> 6300 | T39: 浩天 意大利对接群
G40: 34 | H40: 45752 | M40: 后勤支出 | N40: 2792.003 | O40: 发工资 | P40: 0.63263889 | S40: =SUMIF(I:I,"大表哥 FB&意大利",J:J) -> 2100 | T40: 大表哥 FB&意大利
G41: 35 | H41: 45752 | M41: 后勤支出 | N41: 658.59498 | O41: 发工资 | P41: 0.63333333 | S41: =SUMIF(I:I,"欧洲三不限-泰华3➕1（0.84）",J:J) -> 352.55 | T41: 欧洲三不限-泰华3➕1（0.84）
G42: 36 | H42: 45752 | M42: 后勤支出 | N42: 3745.4435 | O42: 发工资 | P42: 0.63472222 | S42: =SUMIF(I:I,"印度企业户 欧洲美金户下户",J:J) -> 2423.8 | T42: 印度企业户 欧洲美金户下户
...

Sheet 2025年3月收支财务报表
C1: 2025年3月收支财务报表
C4: 财务统计 STATISTICS | G4: 2025年3月收支明细 DETAIL | S4: =SUMIF(M:M,"广告配套",N:N) -> 3258.6167 | T4: U支出的广告配套（不含RMB支出）
G5: 序号 | H5: 日期 | I5: 收入 | M5: 支出
C6: 月份查询 | I6: 项目 | J6: 金额 | K6: 备注 | L6: 时间 | M6: 项目 | N6: 金额 | O6: 备注 | P6: 时间 | S6: =SUMIF(M:M,"后勤支出",N:N) -> 263202.52 | T6: 后勤支出
C7: 3月 | D7: ▼ | G7: 1 | H7: 45717 | I7: 2月结余 | J7: ='2025年2月收支财务报表'!C25 -> 220136.4 | S7: =SUMIF(M:M,"启航广告费",N:N) -> 21044.15 | T7: 启航广告费
C8: 收入 | G8: 2 | H8: 45717 | I8: 浩天 意大利对接群 | J8: 4900 | K8: 退款 | L8: 0.15555556 | M8: 印度003对接—胖鱼 | N8: 6900 | P8: 0.44375 | S8: =SUMIF(M:M,"CH加白户14➕1",N:N) -> 10554.1 | T8: CH加白户14➕1
C9: =C21 -> 1450200.2 | G9: 3 | H9: 45717 | M9: 印度003对接—胖鱼 | N9: 13800 | P9: 0.59513889 | S9: =SUMIF(M:M,"印度企业户 欧洲美金户下户",N:N) -> 19684 | T9: 印度企业户 欧洲美金户下户
C10: 支出 | G10: 4 | H10: 45717 | I10: 意大利张总单导 | J10: 3720 | K10: 2/27 有效9 1080 2/28 有效31 3720 合计 4800 TLimy52jPz279TiS2LDfpCUYsim33dHTew，地址不变，2/27未结 | L10: 0.60694444 | S10: =SUMIF(M:M,"十月二不限——（泰华）",N:N) -> 1457 | T10: 十月二不限
C11: =C23 -> 1126835.1 | G11: 5 | H11: 45717 | I11: 巴西测试粉 | J11: 1657.06 | K11: 服务费15%，1440.92*1.15= 1657.06 | L11: 0.64722222 | S11: =SUMIF(M:M,"深圳芳林子@SHEN 户",N:N) -> 198077 | T11: 深圳芳林子@SHEN 户
C12: 结余 | G12: 6 | H12: 45717 | M12: 后勤支出 | N12: 50000 | O12: 分红B哥2月分红，220,136.40*0.45= 99061.38 | P12: 0.75 | S12: =SUMIF(M:M,"海总- BM户对接",N:N) -> 200 | T12: 海总- BM户对接
C13: =C9-C11 -> 323365.14 | G13: 7 | H13: 45717 | I13: 印度2期 | J13: 100000 | L13: 0.75902778 | S13: =SUMIF(M:M,"账单户充值",N:N) -> 1722.35 | T13: 账单户充值
G14: 8 | H14: 45717 | I14: 印度（10）金山 | J14: 100 | L14: 0.76527778 | S14: =SUMIF(M:M,"Y-5208 FB欧/美户",N:N) -> 10377.563 | T14: Y-5208 FB欧/美户
C15: 任意时段查询 | G15: 9 | H15: 45717 | I15: 印度（10）金山 | J15: 99900 | L15: 0.76597222 | M15: 印度003对接—胖鱼 | N15: 13800 | P15: 0.80208333 | S15: =SUMIF(M:M,"GTHY&papa 二不限 10+2+1",N:N) -> 10 | T15: GTHY&papa 二不限 10+2+1
C16: 起始日期： | G16: 10 | H16: 45717 | M16: 印度003对接—胖鱼 | N16: 9200 | P16: 0.91875 | S16: =SUMIF(M:M,"GT&SHEN 欧 2%+u1",N:N) -> 1635.86 | T16: GT&SHEN 欧 2%+u1
C17: 45292 | G17: 11 | H17: 45718 | M17: 印度003对接—胖鱼 | N17: 23000 | P17: 0.48680556 | S17: =SUMIF(M:M,"欧洲三不限-泰华3➕1（0.84）",N:N) -> 1329.9 | T17: 欧洲三不限-泰华3➕1（0.84）
C18: 结束日期： | G18: 12 | H18: 45718 | I18: 意大利张总单导 | J18: 4560 | K18: 2/27 9 3/1 29 未结算 38*120=4560 | L18: 0.56041667 | M18: 印度003对接—胖鱼 | N18: 35420 | P18: 0.64027778 | S18: =SUMIF(M:M,"哪吒-FB企业海外户",N:N) -> 1734 | T18: 哪吒-FB企业海外户
C19: 72805 | G19: 13 | H19: 45718 | M19: 意大利打群-fa | N19: 6380 | P19: 0.79583333 | S19: =SUMIF(M:M,"海总-全球户",N:N) -> 270 | T19: 海总-全球户
C20: 收入 | G20: 14 | H20: 45718 | M20: 后勤支出 | N20: 49061.38 | O20: 分红B哥2月分红，220,136.40*0.45= 99061.38 | P20: 0.85138889 | S20: =SUMIF(M:M,"Chris Ryan MYM美金户&麦芽-西柚",N:N) -> 100 | T20: Chris Ryan MYM美金户&麦芽-西柚
C21: =SUMIFS(J:J,H:H,">="&$C$17,H:H,"<="&$C$19) -> 1450200.2 | G21: 15 | H21: 45718 | M21: 启航广告费 | N21: 4767.68 | O21: 4000*1.18/0.99=4767.68 | P21: 0.89652778 | S21: =SUMIF(M:M,"海总-越南电信户",N:N) -> 200 | T21: 海总-越南电信户
C22: 支出 | G22: 16 | H22: 45719 | M22: 印度003对接—胖鱼 | N22: 63802 | P22: 0.53333333 | S22: =SUMIF(M:M,"济宁韦宁&香港有意思",N:N) -> 480 | T22: 济宁韦宁&香港有意思
C23: =SUMIFS(N:N,H:H,">="&$C$17,H:H,"<="&$C$19) -> 1126835.1 | G23: 17 | H23: 45719 | M23: 印度驻场-lala(郑总） | N23: 1978 | P23: 0.56875 | S23: =SUMIF(M:M,"凤凰渠道2-泰华",N:N) -> 680 | T23: 凤凰渠道2-泰华
C24: 结余 | G24: 18 | H24: 45719 | I24: 意大利第4梯队（蟑螂哥） | J24: 1680 | K24: 3月2日蟑螂哥 867群 有效3，3*120=360 397群 有效11，11*120=1320 合计 360+1320=1680 | L24: 0.60347222 | S24: =SUMIF(M:M,"海总-黑泽-欧洲户对接",N:N) -> 90 | T24: 海总-黑泽-欧洲户对接
C25: =C21-C23 -> 323365.14 | G25: 19 | H25: 45719 | I25: 印度FB天叶（2/24） | J25: 100 | L25: 0.60486111 | S25: =SUMIF(M:M,"技术学习费",N:N) -> 1288 | T25: 技术学习费
G26: 20 | H26: 45719 | I26: 印度FB天叶（2/24） | J26: 49900 | L26: 0.60902778 | S26: =SUMIF(M:M,"印度FB天叶（2/24）",N:N) -> 26976 | T26: 项目退款：印度FB天叶（2/24）
G27: 21 | H27: 45719 | I27: Y-5208 FB欧/美户 | J27: 485.33 | L27: 0.66736111 | M27: 印度003对接—胖鱼 | N27: 11500 | P27: 0.72986111 | S27: =SUMIF(M:M,"凯旋城7期退款",N:N) -> 15644 | T27: 项目退款：凯旋城7期退款
G28: 22 | H28: 45719 | M28: 启航广告费 | N28: 4116.16 | O28: 500*1.07/0.99+3000*1.18/0.99=4116.16 | P28: 0.73402778 | S28: =SUMIF(M:M,"渠道F 英文J",N:N) -> 2400 | T28: 项目退款：渠道F 英文J
G29: 23 | H29: 45719 | I29: 印度（10）金山 | J29: 100 | L29: 0.81458333 | S29: =SUMIF(M:M,"印度003对接—胖鱼",N:N) -> 346035 | T29: 印度003对接—胖鱼
G30: 24 | H30: 45719 | I30: 印度（10）金山 | J30: 99900 | L30: 0.81597222 | M30: 后勤支出 | N30: 99061.38 | O30: 分红张总2月分红，220,136.40*0.45= 99061.38 | P30: 0.94305556 | S30: =SUMIF(M:M,"印度驻场-lala(郑总）",N:N) -> 89240 | T30: 印度驻场-lala(郑总）
G31: 25 | H31: 45720 | M31: 广告配套 | N31: 900 | O31: 机器人防护 | P31: 0.50138889 | S31: =SUMIF(M:M,"印度FB——哈密瓜",N:N) -> 38295 | T31: 印度FB——哈密瓜
