Workbook

Sheet 明细表
A1: 月份 | B1: 团队 | C1: 业务类型 | D1: 地区 | E1: 项目/代投人名称 | F1: 有效数(粉/人) | G1: 总支出/消耗 | H1: 实际收款 | I1: 项目毛利 | J1: 剩余预付款 | K1: 备注
A2: 11月 | B2: SZ | C2: 自投项目 | D2: 德国 | E2: 德国Summer | F2: 227 | G2: 22713.24 | H2: 40860 | I2: =IF(H2="", "", H2-G2) -> 18146.76 | J2: - | K2: -
A3: 11月 | B3: SZ | C3: 外部代投 | D3: 日本 | E3: 岳总 | F3: 205 | G3: 30750 | H3: 36900 | I3: =IF(H3="", "", H3-G3) -> 6150 | J3: 0 | K3: -
A4: 11月 | B4: SZ | C4: 自投项目 | D4: 新加坡 | E4: 海总-新加坡、加拿大、美国 | F4: 1 | G4: 244.28 | H4: 100 | I4: =IF(H4="", "", H4-G4) -> -144.28 | J4: 5055 | K4: 海总-新加坡、加拿大、美国的预付款是一起的，11月结余合计5055
A5: 11月 | B5: SZ | C5: 自投项目 | D5: 加拿大 | E5: 海总-新加坡、加拿大、美国 | F5: 33 | G5: 6599.76 | H5: 3300 | I5: =IF(H5="", "", H5-G5) -> -3299.76 | J5: 0
A6: 11月 | B6: SZ | C6: 自投项目 | D6: 美国 | E6: 海总-新加坡、加拿大、美国 | F6: 3 | G6: 93.96 | H6: 345 | I6: =IF(H6="", "", H6-G6) -> 251.04 | J6: 0
A7: 11月 | B7: SZ | C7: 自投项目 | D7: 马来 | E7: B哥/马来英语粉 | F7: 1 | G7: 1157.01 | H7: 95 | I7: =IF(H7="", "", H7-G7) -> -1062.01 | J7: 20455 | K7: B哥/马来英语粉11月预付款剩余20455
A8: 11月 | B8: SZ | C8: 自投项目 | D8: 印度 | E8: 印度K4/印度资金测试 | F8: 0 | G8: 110.39 | H8: 0 | I8: =IF(H8="", "", H8-G8) -> -110.39 | J8: 0
A9: 11月 | B9: SZ | C9: 自投项目 | D9: 瑞典 | E9: 瑞典1梯队蟑螂哥渠道 | F9: 0 | G9: 67.43 | H9: 0 | I9: =IF(H9="", "", H9-G9) -> -67.43 | J9: 0
A10: 11月 | B10: SZ | C10: 自投项目 | D10: 比利时 | E10: 海总-比利时单导测试 | F10: 0 | G10: 27.36 | H10: 0 | I10: =IF(H10="", "", H10-G10) -> -27.36 | J10: 0
A11: 11月 | B11: ZZ | C11: 自投项目 | D11: 印度 | E11: 印度资金测试 | F11: 121 | G11: 4129.82 | H11: 0 | I11: =IF(H11="", "", H11-G11) -> -4129.82 | J11: 0 | K11: 12/8 收款20,000
A12: 11月 | B12: ZZ | C12: 自投项目 | D12: 印尼 | E12: 印尼一期 | F12: 0 | G12: 0 | H12: 0 | I12: =IF(H12="", "", H12-G12) -> 0 | J12: 0
A13: 11月 | B13: ZZ | C13: 自投项目 | D13: 印尼 | E13: 印尼二期 | F13: 156 | G13: 6653.77 | H13: 7000 | I13: =IF(H13="", "", H13-G13) -> 346.23 | J13: 0 | K13: 印尼一期二期合计收款7000
A14: 11月 | B14: ZZ | C14: 自投项目 | D14: 马来西亚 | E14: B哥/马来英语粉 | F14: 128 | G14: 5797.11 | H14: 12160 | I14: =IF(H14="", "", H14-G14) -> 6362.89 | J14: =J7 -> 20455 | K14: B哥/马来英语粉11月预付款剩余20455，重复值
A15: 11月 | B15: ZZ | C15: 自投项目 | D15: 尼日利亚 | E15: 尼日利亚 | F15: 0 | G15: 4277.75 | H15: 5768.9 | I15: =IF(H15="", "", H15-G15) -> 1491.15 | J15: 0
A16: 11月 | B16: ZZ | C16: 自投项目 | D16: 德国 | E16: 德国单粉—summer FB180 | F16: 0 | G16: 24.26 | H16: 0 | I16: =IF(H16="", "", H16-G16) -> -24.26 | J16: 0
A17: 11月 | B17: ZZ | C17: 自投项目 | D17: 新加坡 | E17: 海总-新加坡、加拿大、美国 | F17: 15 | G17: 464.5 | H17: 1500 | I17: =IF(H17="", "", H17-G17) -> 1035.5 | J17: =J4 -> 5055 | K17: 海总-新加坡、加拿大、美国的预付款是一起的，11月结余合计5055，重复值
A18: 11月 | B18: ZZ | C18: 自投项目 | D18: 瑞典 | E18: 瑞典1梯队蟑螂哥渠道 | F18: 38 | G18: 9652.06 | H18: 3420 | I18: =IF(H18="", "", H18-G18) -> -6232.06 | J18: 0
A19: 11月 | B19: ZZ | C19: 自投项目 | D19: 韩国 | E19: A1韩国维权粉测试 服务费10% | F19: 0 | G19: 174.52 | H19: 0 | I19: =IF(H19="", "", H19-G19) -> -174.52 | J19: 0
A20: 10月 | B20: ZZ | C20: 自投项目 | D20: 印度 | E20: 印度20期 | F20: 2829 | G20: =20.5375*F20 -> 58100.588 | H20: =F20*31 -> 87699 | I20: =IF(H20="", "", H20-G20) -> 29598.412 | J20: 0
A21: 10月 | B21: ZZ | C21: 自投项目 | D21: 印度 | E21: 印度白马5期 | F21: 1500 | G21: =20.5375*F21 -> 30806.25 | H21: =F21*31 -> 46500 | I21: =IF(H21="", "", H21-G21) -> 15693.75 | J21: 0
A22: 10月 | B22: ZZ | C22: 自投项目 | D22: 印度 | E22: 印度新K1 | F22: 5274 | G22: =20.5375*F22 -> 108314.77 | H22: =F22*31 -> 163494 | I22: =IF(H22="", "", H22-G22) -> 55179.225 | J22: 0
A23: 10月 | B23: ZZ | C23: 自投项目 | D23: 印度 | E23: 印度K4 | F23: 4226 | G23: =20.5375*F23 -> 86791.475 | H23: =F23*31 -> 131006 | I23: =IF(H23="", "", H23-G23) -> 44214.525 | J23: 0
A24: 10月 | B24: ZZ | C24: 自投项目 | D24: 印度 | E24: 印度K26 | F24: 4644 | G24: =20.5375*F24+0.03 -> 95376.18 | H24: =F24*31 -> 143964 | I24: =IF(H24="", "", H24-G24) -> 48587.82 | J24: 0
A25: 10月 | B25: ZZ | C25: 自投项目 | D25: 马来西亚 | E25: B哥/马来英语粉 | F25: 94 | G25: 4885.7803 | H25: 8930 | I25: =IF(H25="", "", H25-G25) -> 4044.2197 | J25: 33355 | K25: B哥/马来英语粉10月预付款剩余33,355
A26: 10月 | B26: ZZ | C26: 自投项目 | D26: 德国 | E26: 德国单粉—summer | F26: 10 | G26: 1918.26 | H26: 1800 | I26: =IF(H26="", "", H26-G26) -> -118.26 | J26: 0 | K26: 预付款已退清
A27: 10月 | B27: ZZ | C27: 自投项目 | D27: 韩国 | E27: A1韩国维权粉测试 服务费10% | F27: 0 | G27: 1685.08 | H27: 0 | I27: =IF(H27="", "", H27-G27) -> -1685.08 | J27: 0
A28: 10月 | B28: ZZ | C28: 自投项目 | D28: 日本 | E28: 渠道106-本土fb🇯🇵 | F28: 0 | G28: 0 | H28: 0 | I28: =IF(H28="", "", H28-G28) -> 0 | J28: 0
A29: 10月 | B29: ZZ | C29: 自投项目 | D29: 尼日利亚 | E29: 尼日利亚 | F29: 0 | G29: 488.3 | H29: 0 | I29: =IF(H29="", "", H29-G29) -> -488.3 | J29: 12060 | K29: 渠道106-本土fb🇯🇵10月预付款剩余12060
A30: 10月 | B30: ZZ | C30: 自投项目 | D30: 比利时 | E30: 海总-比利时单导测试 | F30: 0 | G30: 608.69 | H30: 0 | I30: =IF(H30="", "", H30-G30) -> -608.69 | J30: 0
A31: 10月 | B31: SZ | C31: 外部代投 | D31: 日本 | E31: 岳总 | F31: 164 | G31: =F31*150 -> 24600 | H31: =165*180 -> 29700 | I31: =IF(H31="", "", H31-G31) -> 5100 | J31: 0
A32: 10月 | B32: SZ | C32: 自投项目 | D32: 印度 | E32: 印度20期 | F32: 30 | G32: =F32*60.2389 -> 1807.167 | H32: =F32*31 -> 930 | I32: =IF(H32="", "", H32-G32) -> -877.167 | J32: 0
A33: 10月 | B33: SZ | C33: 自投项目 | D33: 印度 | E33: 印度白马5期 | F33: 0 | G33: =F33*60.2389 -> 0 | H33: =F33*31 -> 0 | I33: =IF(H33="", "", H33-G33) -> 0 | J33: 0
A34: 10月 | B34: SZ | C34: 自投项目 | D34: 印度 | E34: 印度新K1 | F34: 0 | G34: =F34*60.2389 -> 0 | H34: =F34*31 -> 0 | I34: =IF(H34="", "", H34-G34) -> 0 | J34: 0
A35: 10月 | B35: SZ | C35: 自投项目 | D35: 印度 | E35: 印度K4 | F35: 131 | G35: =F35*60.2389 -> 7891.2959 | H35: =F35*31 -> 4061 | I35: =IF(H35="", "", H35-G35) -> -3830.2959 | J35: 0
A36: 10月 | B36: SZ | C36: 自投项目 | D36: 印度 | E36: 印度K26 | F36: 8 | G36: =F36*60.2389 -> 481.9112 | H36: =F36*31 -> 248 | I36: =IF(H36="", "", H36-G36) -> -233.9112 | J36: 0
A37: 10月 | B37: SZ | C37: 自投项目 | D37: 马来西亚 | E37: B哥/马来英语粉 | F37: 90 | G37: 8953.16 | H37: 8550 | I37: =IF(H37="", "", H37-G37) -> -403.16 | J37: 33355 | K37: B哥/马来英语粉10月预付款剩余33,355，重复值
A38: 10月 | B38: SZ | C38: 自投项目 | D38: 日本 | E38: 渠道106-本土fb🇯🇵 | F38: 0 | G38: 0 | H38: 0 | I38: =IF(H38="", "", H38-G38) -> 0 | J38: 0
A39: 10月 | B39: SZ | C39: 自投项目 | D39: 德国 | E39: 德国单粉—summer | F39: 0 | G39: 0 | H39: 0 | I39: =IF(H39="", "", H39-G39) -> 0 | J39: 0
A40: 10月 | B40: SZ | C40: 自投项目 | D40: 比利时 | E40: 海总-比利时单导测试 | F40: 0 | G40: 137.09 | H40: 0 | I40: =IF(H40="", "", H40-G40) -> -137.09 | J40: 0
...

Sheet 成本表
A1: 月份 | B1: 团队 | C1: 员工工资成本 | D1: 运营杂费 | E1: 成本备注
A2: 11月 | B2: SZ | C2: 0 | D2: =4993.46+4162.9 -> 9156.36 | E2: 工资按上月结算，本月不计入。11月运营杂费含公司运营成本4,993.46、广告配套费用4162.9
A3: 11月 | B3: ZZ | C3: 0 | D3: =1939.72+6641.69 -> 8581.41 | E3: 11月运营杂费含公司运营成本1939.72、广告配套费用6,641.69
A4: 10月 | B4: SZ | C4: 7263.79 | D4: =4766.91+5663.34 -> 10430.25 | E4: 10月计提工资。10月运营杂费含公司运营成本4766.91、广告配套费用5663.34、
A5: 10月 | B5: ZZ | C5: 40523.94 | D5: =1315.94+3512.05 -> 4827.99 | E5: 10月运营杂费含公司运营成本1315.94、广告配套费用3512.05、

Sheet 利润表
A1: 月份 | B1: 团队 | C1: 项目总毛利 | D1: (减) 工资成本 | E1: (减) 运营杂费 | F1: 净利润
A2: 11月 | B2: SZ | C2: =SUMIFS('明细表'!$I:$I, '明细表'!$A:$A, $A2, '明细表'!$B:$B, $B2) -> 19836.57 | D2: =SUMIFS('成本表'!$C:$C, '成本表'!$A:$A, $A2, '成本表'!$B:$B, $B2) -> 0 | E2: =SUMIFS('成本表'!$D:$D, '成本表'!$A:$A, $A2, '成本表'!$B:$B, $B2) -> 9156.36 | F2: =C2 - D2 - E2 -> 10680.21 | H2: SZ (10月利润-18075.66+11月利润10680.21)*0.4-印度谷歌（32）6144/2=-6,030.18
A3: 11月 | B3: ZZ | C3: =SUMIFS('明细表'!$I:$I, '明细表'!$A:$A, $A3, '明细表'!$B:$B, $B3) -> -1324.89 | D3: =SUMIFS('成本表'!$C:$C, '成本表'!$A:$A, $A3, '成本表'!$B:$B, $B3) -> 0 | E3: =SUMIFS('成本表'!$D:$D, '成本表'!$A:$A, $A3, '成本表'!$B:$B, $B3) -> 8581.41 | F3: =C3 - D3 - E3 -> -9906.3 | H3: ZZ(10月利润149065.69-11月利润9906.3)*0.1=13916
A4: 10月 | B4: SZ | C4: =SUMIFS('明细表'!$I:$I, '明细表'!$A:$A, $A4, '明细表'!$B:$B, $B4) -> -381.6241 | D4: =SUMIFS('成本表'!$C:$C, '成本表'!$A:$A, $A4, '成本表'!$B:$B, $B4) -> 7263.79 | E4: =SUMIFS('成本表'!$D:$D, '成本表'!$A:$A, $A4, '成本表'!$B:$B, $B4) -> 10430.25 | F4: =C4 - D4 - E4 -> -18075.664 | H4: -6,030.18+13915.939=7,885.76（公司欠LH）+864.994（WS垫付）=8,750.75
A5: 10月 | B5: ZZ | C5: =SUMIFS('明细表'!$I:$I, '明细表'!$A:$A, $A5, '明细表'!$B:$B, $B5) -> 194417.62 | D5: =SUMIFS('成本表'!$C:$C, '成本表'!$A:$A, $A5, '成本表'!$B:$B, $B5) -> 40523.94 | E5: =SUMIFS('成本表'!$D:$D, '成本表'!$A:$A, $A5, '成本表'!$B:$B, $B5) -> 4827.99 | F5: =C5 - D5 - E5 -> 149065.69
